Workbook

Sheet מסך ניווט מרכזי
P1: סוג (Type) | Q1: קוד (Code) | R1: עברית | S1: English | T1: גיליון (Sheet) | U1: תא (Cell) | V1: קישור (Link)
B2: CBC ISRAEL | SAP PM - מסך ניווט מרכזי | J2: ★ CBC ISRAEL Project NEO | P2: טבלה | Q2: IFLOT | R2: רשומת אב של מיקום פונקציונלי | S2: Functional location master record | T2: 1. מבנה ארגוני ותשתית | U2: A3 | V2: =HYPERLINK("#'"&T2&"'!"&U2,"➜ פתח")
B3: Project NEO - ECC 6.0 ➜ S/4HANA Migration | Plant Maintenance / EAM | P3: שדה | Q3: TPLNR | R3: מספר מיקום פונקציונלי | S3: Functional location number | T3: 1. מבנה ארגוני ותשתית | U3: D4 | V3: =HYPERLINK("#'"&T3&"'!"&U3,"➜ פתח")
P4: שדה | Q4: STRNO | R4: מספר מבנה מעוצב | S4: Formatted / structured number | T4: 1. מבנה ארגוני ותשתית | U4: D5 | V4: =HYPERLINK("#'"&T4&"'!"&U4,"➜ פתח")
B5: סיכום התקדמות מיגרציה (KPI - מתעדכן אוטומטית מ-Cockpit) | P5: שדה | Q5: FLTYP | R5: קטגוריית מיקום | S5: Functional location category | T5: 1. מבנה ארגוני ותשתית | U5: D6 | V5: =HYPERLINK("#'"&T5&"'!"&U5,"➜ פתח")
B6: =COUNTA('Cockpit מעקב מיגרציה'!$C$8:$C$65) | C6: =COUNTIF('Cockpit מעקב מיגרציה'!$D$8:$D$65,"Done") | D6: =COUNTIF('Cockpit מעקב מיגרציה'!$D$8:$D$65,"Tested") | E6: =(COUNTIF('Cockpit מעקב מיגרציה'!$D$8:$D$65,"In analysis")+COUNTIF('Cockpit מעקב מיגרציה'!$D$8:$D$65,"In conversion")) | F6: =COUNTIF('Cockpit מעקב מיגרציה'!$D$8:$D$65,"Not started") | G6: =IFERROR((COUNTIF('Cockpit מעקב מיגרציה'!$D$8:$D$65,"Done"))/(COUNTA('Cockpit מעקב מיגרציה'!$C$8:$C$65)),0) | P6: שדה | Q6: TPLKZ | R6: מחוון מבנה / מסיכת קידוד | S6: Structure indicator (edit mask) | T6: 1. מבנה ארגוני ותשתית | U6: D7 | V6: =HYPERLINK("#'"&T6&"'!"&U6,"➜ פתח")
B7: סה"כ אובייקטים | C7: הושלם (Done) | D7: נבדק (Tested) | E7: בתהליך (In Progress) | F7: פתוח (Open) | G7: % השלמה | P7: שדה | Q7: TPLMA | R7: מיקום אב בהיררכיה | S7: Superior functional location | T7: 1. מבנה ארגוני ותשתית | U7: D8 | V7: =HYPERLINK("#'"&T7&"'!"&U7,"➜ פתח")
P8: שדה | Q8: OBJNR | R8: מפתח אובייקט לסטטוס | S8: Object number (status) | T8: 1. מבנה ארגוני ותשתית | U8: D9 | V8: =HYPERLINK("#'"&T8&"'!"&U8,"➜ פתח")
B9: ניווט מהיר לגיליונות (לחץ על כרטיס כדי לעבור) | P9: טרנזקציה | Q9: IL01 | R9: רשומת אב של מיקום פונקציונלי | S9: Functional location master record | T9: 1. מבנה ארגוני ותשתית | U9: A4 | V9: =HYPERLINK("#'"&T9&"'!"&U9,"➜ פתח")
B10: 1. מבנה ארגוני ותשתית | D10: 2. ציוד ונתוני מאסטר | F10: 3. עצי מוצר של אחזקה (BOM) | H10: 4. נקודות מדידה ומונים | P10: טרנזקציה | Q10: IL02 | R10: רשומת אב של מיקום פונקציונלי | S10: Functional location master record | T10: 1. מבנה ארגוני ותשתית | U10: A4 | V10: =HYPERLINK("#'"&T10&"'!"&U10,"➜ פתח")
P11: טרנזקציה | Q11: IL03 | R11: רשומת אב של מיקום פונקציונלי | S11: Functional location master record | T11: 1. מבנה ארגוני ותשתית | U11: A4 | V11: =HYPERLINK("#'"&T11&"'!"&U11,"➜ פתח")
P12: טרנזקציה | Q12: IH01 | R12: רשומת אב של מיקום פונקציונלי | S12: Functional location master record | T12: 1. מבנה ארגוני ותשתית | U12: A4 | V12: =HYPERLINK("#'"&T12&"'!"&U12,"➜ פתח")
B13: 5. קטלוגים, קודים ופרופילים | D13: 6. הודעות אחזקה (Notifications) | F13: 7. פקודות עבודה (פק"ע) | H13: 8. ניהול סטטוסים (Status Mgmt) | P13: טרנזקציה | Q13: IH06 | R13: רשומת אב של מיקום פונקציונלי | S13: Functional location master record | T13: 1. מבנה ארגוני ותשתית | U13: A4 | V13: =HYPERLINK("#'"&T13&"'!"&U13,"➜ פתח")
P14: פונקציה | Q14: BAPI_FUNCLOC_CREATE | R14: יצירת מיקום פונקציונלי דרך ממשק תקני | S14: Functional location master record | T14: 1. מבנה ארגוני ותשתית | U14: G4 | V14: =HYPERLINK("#'"&T14&"'!"&U14,"➜ פתח")
P15: פונקציה | Q15: BAPI_FUNCLOC_CHANGE | R15: שינוי מיקום פונקציונלי | S15: Functional location master record | T15: 1. מבנה ארגוני ותשתית | U15: G4 | V15: =HYPERLINK("#'"&T15&"'!"&U15,"➜ פתח")
B16: 9. אינטגרציית מלאי ורכש (PM-MM) | D16: 10. עלויות והתחשבנות (PM-CO) | F16: 11. אחזקה מונעת ותוכניות | H16: 12. היסטוריה וארכיון | P16: פונקציה | Q16: BAPI_FUNCLOC_GETDETAIL | R16: שליפת פרטי מיקום | S16: Functional location master record | T16: 1. מבנה ארגוני ותשתית | U16: G4 | V16: =HYPERLINK("#'"&T16&"'!"&U16,"➜ פתח")
P17: פונקציה | Q17: ISU_FUNCLOC_GETLIST | R17: שליפת רשימת מיקומים לפי בחירה | S17: Functional location master record | T17: 1. מבנה ארגוני ותשתית | U17: G4 | V17: =HYPERLINK("#'"&T17&"'!"&U17,"➜ פתח")
P18: תוכנית | Q18: RIIFLO20 | R18: רשימת מיקומים פונקציונליים (IH06) | S18: Functional location master record | T18: 1. מבנה ארגוני ותשתית | U18: I4 | V18: =HYPERLINK("#'"&T18&"'!"&U18,"➜ פתח")
B19: ★ Simplification Item list | D19: ◆ Cockpit מעקב מיגרציה | F19: ⚙ Custom Code Check | H19: ⇄ ER - Join Map | P19: תוכנית | Q19: RIFLET00 | R19: תחזוקת קטגוריות ומסיכות עריכה | S19: Functional location master record | T19: 1. מבנה ארגוני ותשתית | U19: I4 | V19: =HYPERLINK("#'"&T19&"'!"&U19,"➜ פתח")
P20: Fiori | Q20: Manage Technical Objects (F2079) | R20: רשומת אב של מיקום פונקציונלי | S20: Functional location master record | T20: 1. מבנה ארגוני ותשתית | U20: N4 | V20: =HYPERLINK("#'"&T20&"'!"&U20,"➜ פתח")
P21: טבלה | Q21: IFLOS | R21: תוויות מיקום פונקציונלי (Labels - טבלת ילד של IFLOT) | S21: Functional location labels (child of IFLOT) | T21: 1. מבנה ארגוני ותשתית | U21: A11 | V21: =HYPERLINK("#'"&T21&"'!"&U21,"➜ פתח")
B22: מקרא מותג CBC: אדום=תנועתי/עוגני-על | צפחה=נתוני אב וכותרות | כסף=אינטגרציה ועמודות S/4HANA | P22: שדה | Q22: TPLNR | R22: מיקום פונקציונלי (פנימי) - מצטרף ל-IFLOT | S22: Functional location (internal) - joins IFLOT | T22: 1. מבנה ארגוני ותשתית | U22: D12 | V22: =HYPERLINK("#'"&T22&"'!"&U22,"➜ פתח")
P23: שדה | Q23: STRNO | R23: מספר תווית חיצוני / מובנה | S23: External / structured label number | T23: 1. מבנה ארגוני ותשתית | U23: D13 | V23: =HYPERLINK("#'"&T23&"'!"&U23,"➜ פתח")
B24: 🔍 חיפוש גלובלי (טבלה / טרנזקציה / שדה / פונקציה - עברית או אנגלית) | P24: שדה | Q24: TPLKZ | R24: מחוון מבנה | S24: Structure indicator | T24: 1. מבנה ארגוני ותשתית | U24: D14 | V24: =HYPERLINK("#'"&T24&"'!"&U24,"➜ פתח")
B25: הקלד כאן: | P25: שדה | Q25: TPLVL | R25: רמת היררכיה של התווית | S25: Hierarchy level of label | T25: 1. מבנה ארגוני ותשתית | U25: D15 | V25: =HYPERLINK("#'"&T25&"'!"&U25,"➜ פתח")
P26: שדה | Q26: BEGRU | R26: קבוצת הרשאה | S26: Authorization group | T26: 1. מבנה ארגוני ותשתית | U26: D16 | V26: =HYPERLINK("#'"&T26&"'!"&U26,"➜ פתח")
B27: קישור | C27: קוד / שם טכני | D27: פירוש בעברית | E27: English | F27: גיליון | G27: תא | P27: טרנזקציה | Q27: IL01 | R27: תוויות מיקום פונקציונלי (Labels - טבלת ילד של IFLOT) | S27: Functional location labels (child of IFLOT) | T27: 1. מבנה ארגוני ותשתית | U27: A12 | V27: =HYPERLINK("#'"&T27&"'!"&U27,"➜ פתח")
B28: =IF(C25="","הקלד מונח בתא הצהוב למעלה - והתוצאות יופיעו כאן מיד (כולל קישור לחיץ)...",IFERROR(_xlfn._xlws.FILTER(CHOOSE({1,2,3,4,5,6},$V$2:$V$906,$Q$2:$Q$906,$R$2:$R$906,$S$2:$S$906,$T$2:$T$906,$U$2:$U$906),(ISNUMBER(SEARCH(C25,$Q$2:$Q$906)))+(ISNUMBER(SEARCH(C25,$R$2:$R$906)))+(ISNUMBER(SEARCH(C25,$S$2:$S$906)))+(ISNUMBER(SEARCH(C25,$P$2:$P$906)))>0),"לא נמצאו תוצאות - נסה מונח אחר")) | P28: טרנזקציה | Q28: IL02 | R28: תוויות מיקום פונקציונלי (Labels - טבלת ילד של IFLOT) | S28: Functional location labels (child of IFLOT) | T28: 1. מבנה ארגוני ותשתית | U28: A12 | V28: =HYPERLINK("#'"&T28&"'!"&U28,"➜ פתח")
P29: טרנזקציה | Q29: IL03 | R29: תוויות מיקום פונקציונלי (Labels - טבלת ילד של IFLOT) | S29: Functional location labels (child of IFLOT) | T29: 1. מבנה ארגוני ותשתית | U29: A12 | V29: =HYPERLINK("#'"&T29&"'!"&U29,"➜ פתח")
P30: טרנזקציה | Q30: IH06 | R30: תוויות מיקום פונקציונלי (Labels - טבלת ילד של IFLOT) | S30: Functional location labels (child of IFLOT) | T30: 1. מבנה ארגוני ותשתית | U30: A12 | V30: =HYPERLINK("#'"&T30&"'!"&U30,"➜ פתח")
P31: פונקציה | Q31: BAPI_FUNCLOC_GETDETAIL | R31: שליפת פרטי מיקום כולל תוויות | S31: Functional location labels (child of IFLOT) | T31: 1. מבנה ארגוני ותשתית | U31: G12 | V31: =HYPERLINK("#'"&T31&"'!"&U31,"➜ פתח")
P32: פונקציה | Q32: FUNC_LOCATION_LABEL_READ | R32: קריאת תווית מיקום פונקציונלי | S32: Functional location labels (child of IFLOT) | T32: 1. מבנה ארגוני ותשתית | U32: G12 | V32: =HYPERLINK("#'"&T32&"'!"&U32,"➜ פתח")
P33: תוכנית | Q33: RIIFLO20 | R33: רשימת מיקומים ותוויות (IH06) | S33: Functional location labels (child of IFLOT) | T33: 1. מבנה ארגוני ותשתית | U33: I12 | V33: =HYPERLINK("#'"&T33&"'!"&U33,"➜ פתח")
P34: Fiori | Q34: Manage Technical Objects (F2079) | R34: תוויות מיקום פונקציונלי (Labels - טבלת ילד של IFLOT) | S34: Functional location labels (child of IFLOT) | T34: 1. מבנה ארגוני ותשתית | U34: N12 | V34: =HYPERLINK("#'"&T34&"'!"&U34,"➜ פתח")
P35: טבלה | Q35: ILOA | R35: נתוני מיקום וחיוב משותפים | S35: PM object location & account assignment | T35: 1. מבנה ארגוני ותשתית | U35: A18 | V35: =HYPERLINK("#'"&T35&"'!"&U35,"➜ פתח")
P36: שדה | Q36: ILOAN | R36: מפתח נתוני מיקום/חיוב | S36: Location & account assignment key | T36: 1. מבנה ארגוני ותשתית | U36: D19 | V36: =HYPERLINK("#'"&T36&"'!"&U36,"➜ פתח")
P37: שדה | Q37: KOSTL | R37: מרכז עלות | S37: Cost center | T37: 1. מבנה ארגוני ותשתית | U37: D20 | V37: =HYPERLINK("#'"&T37&"'!"&U37,"➜ פתח")
P38: שדה | Q38: SWERK | R38: מפעל אחזקה | S38: Maintenance plant | T38: 1. מבנה ארגוני ותשתית | U38: D21 | V38: =HYPERLINK("#'"&T38&"'!"&U38,"➜ פתח")
P39: שדה | Q39: INGRP | R39: קבוצת תכנון | S39: Planner group | T39: 1. מבנה ארגוני ותשתית | U39: D22 | V39: =HYPERLINK("#'"&T39&"'!"&U39,"➜ פתח")
P40: שדה | Q40: GEWRK | R40: מרכז עבודה ראשי | S40: Main work center | T40: 1. מבנה ארגוני ותשתית | U40: D23 | V40: =HYPERLINK("#'"&T40&"'!"&U40,"➜ פתח")
...

Sheet 1. מבנה ארגוני ותשתית
A1: ◄ חזרה למסך הראשי | C1: 1. מבנה ארגוני ותשתית | ECC 6.0 ➜ S/4HANA · CBC NEO
A2: מס' (#) | B2: טרנזקציות ECC (Main & Secondary) | C2: טבלת בסיס (Core Table) | D2: שדה טכני (Field) | E2: Field (English) | F2: שדה (עברית) | G2: סוג מפתח (Key Type) | H2: פונקציות / BAPIs | I2: תיאור הפונקציה | J2: תוכניות / דוחות | K2: תיאור התוכנית | L2: סטטוס S/4HANA | M2: טבלה/שדה חלופי ב-S/4 | N2: טרנז'/תוכנית מחליפה ב-S/4 | O2: אפליקציית Fiori (שם + ID) | P2: שלב מיגרציה / הערות SUM Conversion
A3: ◆ טבלה IFLOT - רשומת אב של מיקום פונקציונלי (Functional location master record)
A4: 1 | B4: IL01/IL02/IL03; IH01, IH06 | C4: IFLOT | D4: TPLNR | E4: Functional location number | F4: מספר מיקום פונקציונלי | G4: PK | H4: • BAPI_FUNCLOC_CREATE • BAPI_FUNCLOC_CHANGE • BAPI_FUNCLOC_GETDETAIL • ISU_FUNCLOC_GETLIST | I4: • יצירת מיקום פונקציונלי דרך ממשק תקני • שינוי מיקום פונקציונלי • שליפת פרטי מיקום • שליפת רשימת מיקומים לפי בחירה | J4: • RIIFLO20 • RIFLET00 | K4: • רשימת מיקומים פונקציונליים (IH06) • תחזוקת קטגוריות ומסיכות עריכה | L4: ללא שינוי במודל הנתונים (תואם) | M4: IFLOT (זהה) | N4: IL01-03 נתמכים; אסטרטגי: Fiori | O4: Manage Technical Objects (F2079) | P4: ללא פעולת המרה ייעודית ב-SUM (טבלה תואמת). מומלץ Regression Test ואימות התאמות אישיות לאחר ההמרה.
A5: 2 | D5: STRNO | E5: Formatted / structured number | F5: מספר מבנה מעוצב | G5: -
A6: 3 | D6: FLTYP | E6: Functional location category | F6: קטגוריית מיקום | G6: -
A7: 4 | D7: TPLKZ | E7: Structure indicator (edit mask) | F7: מחוון מבנה / מסיכת קידוד | G7: -
A8: 5 | D8: TPLMA | E8: Superior functional location | F8: מיקום אב בהיררכיה | G8: FK
A9: 6 | D9: OBJNR | E9: Object number (status) | F9: מפתח אובייקט לסטטוס | G9: FK
A11: ◆ טבלה IFLOS - תוויות מיקום פונקציונלי (Labels - טבלת ילד של IFLOT) (Functional location labels (child of IFLOT))
A12: 7 | B12: IL01/IL02/IL03; IH06 | C12: IFLOS | D12: TPLNR | E12: Functional location (internal) - joins IFLOT | F12: מיקום פונקציונלי (פנימי) - מצטרף ל-IFLOT | G12: PK/FK | H12: • BAPI_FUNCLOC_GETDETAIL • FUNC_LOCATION_LABEL_READ | I12: • שליפת פרטי מיקום כולל תוויות • קריאת תווית מיקום פונקציונלי | J12: • RIIFLO20 | K12: • רשימת מיקומים ותוויות (IH06) | L12: ללא שינוי (תואם) | M12: IFLOS (זהה) | N12: IL01-03; Fiori | O12: Manage Technical Objects (F2079) | P12: ללא פעולת המרה ייעודית ב-SUM (טבלה תואמת). מומלץ Regression Test ואימות התאמות אישיות לאחר ההמרה.
A13: 8 | D13: STRNO | E13: External / structured label number | F13: מספר תווית חיצוני / מובנה | G13: -
A14: 9 | D14: TPLKZ | E14: Structure indicator | F14: מחוון מבנה | G14: FK
A15: 10 | D15: TPLVL | E15: Hierarchy level of label | F15: רמת היררכיה של התווית | G15: -
A16: 11 | D16: BEGRU | E16: Authorization group | F16: קבוצת הרשאה | G16: -
A18: ◆ טבלה ILOA - נתוני מיקום וחיוב משותפים (PM object location & account assignment)
A19: 12 | B19: IL02; IE02 (ירושה) | C19: ILOA | D19: ILOAN | E19: Location & account assignment key | F19: מפתח נתוני מיקום/חיוב | G19: PK | H19: • ILOA_READ • ILOA_UPDATE • ILOA_INHERIT_FROM_FUNCLOC | I19: • קריאת נתוני מיקום/חיוב • עדכון נתוני מיקום/חיוב • ירושת נתונים מהמיקום לציוד | J19: • RILOAA00 | K19: • התאמת נתוני מיקום/חיוב באובייקטים | L19: ללא שינוי (תואם) | M19: ILOA (זהה) | N19: ללא; מנוהל דרך אובייקט טכני | O19: Manage Technical Objects (F2079) | P19: ללא פעולת המרה ייעודית ב-SUM (טבלה תואמת). מומלץ Regression Test ואימות התאמות אישיות לאחר ההמרה.
A20: 13 | D20: KOSTL | E20: Cost center | F20: מרכז עלות | G20: FK
A21: 14 | D21: SWERK | E21: Maintenance plant | F21: מפעל אחזקה | G21: FK
A22: 15 | D22: INGRP | E22: Planner group | F22: קבוצת תכנון | G22: FK
A23: 16 | D23: GEWRK | E23: Main work center | F23: מרכז עבודה ראשי | G23: FK
A24: 17 | D24: TPLNR | E24: Functional location | F24: מיקום פונקציונלי | G24: FK
A26: ◆ טבלה CRHD - כותרת מרכז עבודה (Work center header)
A27: 18 | B27: IR01/IR02/IR03; CR05, CR06 | C27: CRHD | D27: OBJID | E27: Internal work center object ID | F27: מזהה אובייקט פנימי | G27: PK | H27: • CR_WORKCENTER_READ • CRAP_WORKCENTER_GET_DETAIL | I27: • קריאת נתוני מרכז עבודה • שליפת פרטי מרכז עבודה | J27: • RCRACO00 | K27: • דוח מרכזי עבודה וקיבולות | L27: ללא שינוי (תואם) | M27: CRHD (זהה) | N27: IR01-03 / CR0*; Fiori | O27: Manage Work Centers (אמת ID) | P27: ללא פעולת המרה ייעודית ב-SUM (טבלה תואמת). מומלץ Regression Test ואימות התאמות אישיות לאחר ההמרה.
A28: 19 | D28: ARBPL | E28: Work center code | F28: קוד מרכז עבודה | G28: -
A29: 20 | D29: OBJTY | E29: Object type ('A'=work center) | F29: סוג אובייקט | G29: PK
A30: 21 | D30: WERKS | E30: Plant | F30: מפעל | G30: FK
A31: 22 | D31: VERWE | E31: Work center usage | F31: שימוש מרכז עבודה | G31: -
A32: 23 | D32: VERAN | E32: Person responsible | F32: אחראי | G32: -
A34: ◆ טבלה CRTX - טקסטים של מרכז עבודה (Work center texts)
A35: 24 | B35: IR02; IR03 | C35: CRTX | D35: OBJID | E35: Work center object ID | F35: מזהה אובייקט | G35: PK/FK | H35: • CR_TEXT_READ | I35: • קריאת טקסט מרכז עבודה | J35: • RCRACO00 | K35: • דוח מרכזי עבודה | L35: ללא שינוי (תואם) | M35: CRTX (זהה) | N35: IR0*; Fiori | O35: Manage Work Centers (אמת ID) | P35: ללא פעולת המרה ייעודית ב-SUM (טבלה תואמת). מומלץ Regression Test ואימות התאמות אישיות לאחר ההמרה.
A36: 25 | D36: SPRAS | E36: Language key | F36: שפה | G36: PK
A37: 26 | D37: KTEXT | E37: Work center description | F37: תיאור מרכז עבודה | G37: -
A39: ◆ טבלה T370T - טבלת טקסט להגדרות מבנה/קטגוריות PM (Customizing) (PM structure/category customizing text table)
A40: 27 | B40: SPRO; OIA1, OIMR | C40: T370T | D40: SPRAS | E40: Language key | F40: שפה | G40: PK | H40: • STRUCTURE_INDICATOR_READ | I40: • קריאת מחוון מבנה והגדרותיו | J40: • RIFLET00 | K40: • תחזוקת קטגוריות ומסיכות עריכה | L40: ללא שינוי (Customizing תואם) | M40: T370T (זהה) | N40: SPRO (זהה) | O40: אין Fiori ייעודי (Customizing) | P40: ללא פעולת המרה ייעודית ב-SUM (טבלה תואמת). מומלץ Regression Test ואימות התאמות אישיות לאחר ההמרה.
A41: 28 | D41: FLTYP | E41: Functional location category | F41: קטגוריית מיקום | G41: PK
A42: 29 | D42: FLTYPT | E42: Category description | F42: תיאור קטגוריה | G42: -
A45: ⚙ הרחבות טכניות ושינויי ארכיטקטורה (Technical Extensions: User Exits / BAdIs / ECC vs S/4HANA)
A46: סוג (Type) | C46: קוד / שם טכני (Code) | E46: תיאור / הבדל (Hebrew)
A47: User Exit (SMOD) | C47: ITOB0001 | E47: הרחבת לקוח לאובייקטים טכניים (מיקום/ציוד) - שדות נוספים ובדיקות
...

Sheet 2. ציוד ונתוני מאסטר
A1: ◄ חזרה למסך הראשי | C1: 2. ציוד ונתוני מאסטר | ECC 6.0 ➜ S/4HANA · CBC NEO
A2: מס' (#) | B2: טרנזקציות ECC (Main & Secondary) | C2: טבלת בסיס (Core Table) | D2: שדה טכני (Field) | E2: Field (English) | F2: שדה (עברית) | G2: סוג מפתח (Key Type) | H2: פונקציות / BAPIs | I2: תיאור הפונקציה | J2: תוכניות / דוחות | K2: תיאור התוכנית | L2: סטטוס S/4HANA | M2: טבלה/שדה חלופי ב-S/4 | N2: טרנז'/תוכנית מחליפה ב-S/4 | O2: אפליקציית Fiori (שם + ID) | P2: שלב מיגרציה / הערות SUM Conversion
A3: ◆ טבלה EQUI - רשומת אב של ציוד (Equipment master record)
A4: 1 | B4: IE01/IE02/IE03; IH08, IE05 | C4: EQUI | D4: EQUNR | E4: Equipment number | F4: מספר ציוד | G4: PK | H4: • BAPI_EQUI_CREATE • BAPI_EQUI_CHANGE • BAPI_EQUI_GETDETAIL • BAPI_EQMT_INSTALL | I4: • יצירת ציוד דרך ממשק תקני • שינוי ציוד • שליפת פרטי ציוד • התקנת ציוד במיקום/ציוד אב | J4: • RIEQUI20 • RIEQUI00 | K4: • רשימת ציוד (IH08) • ניתוח היסטוריית התקנות הציוד | L4: ללא שינוי במודל הנתונים (תואם) | M4: EQUI (זהה) | N4: IE01-03 נתמכים; אסטרטגי: Fiori | O4: Manage Technical Objects (F2079) | P4: ללא פעולת המרה ייעודית ב-SUM (טבלה תואמת). מומלץ Regression Test ואימות התאמות אישיות לאחר ההמרה.
A5: 2 | D5: EQTYP | E5: Equipment category | F5: קטגוריית ציוד | G5: -
A6: 3 | D6: EQART | E6: Technical object type | F6: סוג טכני | G6: -
A7: 4 | D7: HERST | E7: Manufacturer | F7: יצרן | G7: -
A8: 5 | D8: TYPBZ | E8: Manufacturer model number | F8: דגם היצרן | G8: -
A9: 6 | D9: OBJNR | E9: Object number (status) | F9: מפתח אובייקט לסטטוס | G9: FK
A11: ◆ טבלה EQKT - טקסטים (תיאורים) של ציוד (Equipment short texts)
A12: 7 | B12: IE02; IE03 | C12: EQKT | D12: EQUNR | E12: Equipment number | F12: מספר ציוד | G12: PK/FK | H12: • EQUIPMENT_TEXT_READ | I12: • קריאת טקסט ציוד | J12: • RIEQUI20 | K12: • רשימת ציוד עם תיאורים | L12: ללא שינוי (תואם) | M12: EQKT (זהה) | N12: IE0*; Fiori | O12: Manage Technical Objects (F2079) | P12: ללא פעולת המרה ייעודית ב-SUM (טבלה תואמת). מומלץ Regression Test ואימות התאמות אישיות לאחר ההמרה.
A13: 8 | D13: SPRAS | E13: Language key | F13: שפה | G13: PK
A14: 9 | D14: EQKTX | E14: Equipment description | F14: תיאור הציוד | G14: -
A16: ◆ טבלה EQUZ - פלח זמן של ציוד (התקנות/שיוך) (Equipment time segment)
A17: 10 | B17: IE02; IE4N (התקנה/פירוק) | C17: EQUZ | D17: EQUNR | E17: Equipment number | F17: מספר ציוד | G17: PK/FK | H17: • EQUI_TIMESEGMENT_READ • EQUIPMENT_DISMANTLE | I17: • קריאת פלחי הזמן של הציוד • פירוק ציוד מהמיקום/ציוד אב | J17: • RIEQUI00 | K17: • ניתוח שינויי התקנה והיסטוריה | L17: ללא שינוי (תואם) | M17: EQUZ (זהה) | N17: IE4N נתמך; Fiori | O17: Manage Technical Objects (F2079) | P17: ללא פעולת המרה ייעודית ב-SUM (טבלה תואמת). מומלץ Regression Test ואימות התאמות אישיות לאחר ההמרה.
A18: 11 | D18: DATBI | E18: Valid-to date of segment | F18: תקף עד | G18: PK
A19: 12 | D19: HEQUI | E19: Superior equipment | F19: ציוד עליון | G19: FK
A20: 13 | D20: ILOAN | E20: Location/account key | F20: מפתח מיקום/חיוב | G20: FK
A21: 14 | D21: EQLFN | E21: Time segment counter | F21: מונה פלח זמן | G21: PK
A23: ◆ טבלה OBJK - רשימת אובייקטים / מספרים סידוריים (Object list / serial assignment)
A24: 15 | B24: IQ01/IQ02/IQ03; IQ08, IQ09 | C24: OBJK | D24: OBKNR | E24: Object list number | F24: מספר רשומת אובייקט | G24: PK | H24: • SERIAL_NUMBER_CREATE • SERNR_ADD_TO_DOCUMENT • BAPI_OBJCL_CREATE | I24: • יצירת מספר סידורי • שיוך סריאל לתעודת מלאי • שיוך סיווג לאובייקט | J24: • RISERNR0 | K24: • דוח סריאלים מול תנועות מלאי | L24: ללא שינוי (תואם) | M24: OBJK (זהה) | N24: IQ0*; Fiori | O24: Manage Technical Objects (F2079) | P24: ללא פעולת המרה ייעודית ב-SUM (טבלה תואמת). מומלץ Regression Test ואימות התאמות אישיות לאחר ההמרה.
A25: 16 | D25: EQUNR | E25: Equipment number | F25: מספר ציוד | G25: FK
A26: 17 | D26: SERNR | E26: Serial number | F26: מספר סידורי | G26: -
A27: 18 | D27: MATNR | E27: Material number | F27: חומר | G27: FK
A28: 19 | D28: TASER | E28: Serial number profile usage | F28: שימוש פרופיל סריאלי | G28: -
A31: ⚙ הרחבות טכניות ושינויי ארכיטקטורה (Technical Extensions: User Exits / BAdIs / ECC vs S/4HANA)
A32: סוג (Type) | C32: קוד / שם טכני (Code) | E32: תיאור / הבדל (Hebrew)
A33: User Exit (SMOD) | C33: IEQM0001 | E33: בדיקות והרחבת שדות בעת יצירת/שינוי ציוד
A34: User Exit (SMOD) | C34: IEQM0003 | E34: ברירות מחדל וקביעת ערכים אוטומטית לציוד
A35: User Exit (SMOD) | C35: ISER0001 | E35: הרחבת לוגיקת מספרים סידוריים (Serialization)
A36: BAdI (SE18) | C36: BADI_EAM_TECHNICAL_OBJECT | E36: הרחבת לוגיקת ציוד/אובייקט טכני ב-S/4HANA
A37: BAdI (SE18) | C37: EAM_SERNR_ADD_DATA | E37: הרחבת נתוני מספר סידורי (אמת שם מדויק ב-SE18)
A38: ארכיטקטורה ECC↔S/4 | C38: — | E38: מודל EQUI/EQUZ/ILOA ללא שינוי; ירושת נתוני מיקום נשמרת.
A39: ארכיטקטורה ECC↔S/4 | C39: — | E39: ב-S/4 אינטגרציה אופציונלית ל-Asset Central Foundation / IoT לניטור מצב.
A40: ארכיטקטורה ECC↔S/4 | C40: — | E40: Classification (סיווג) תואם; שדה MATNR בציוד מושפע מהארכת אורך חומר ל-40 תווים.

Sheet 3. עצי מוצר של אחזקה (BOM)
A1: ◄ חזרה למסך הראשי | C1: 3. עצי מוצר של אחזקה (BOM) | ECC 6.0 ➜ S/4HANA · CBC NEO
A2: מס' (#) | B2: טרנזקציות ECC (Main & Secondary) | C2: טבלת בסיס (Core Table) | D2: שדה טכני (Field) | E2: Field (English) | F2: שדה (עברית) | G2: סוג מפתח (Key Type) | H2: פונקציות / BAPIs | I2: תיאור הפונקציה | J2: תוכניות / דוחות | K2: תיאור התוכנית | L2: סטטוס S/4HANA | M2: טבלה/שדה חלופי ב-S/4 | N2: טרנז'/תוכנית מחליפה ב-S/4 | O2: אפליקציית Fiori (שם + ID) | P2: שלב מיגרציה / הערות SUM Conversion
A3: ◆ טבלה STKO - כותרת עץ מוצר (BOM header)
A4: 1 | B4: IB01/CS01; CS02/CS03 | C4: STKO | D4: STLNR | E4: Bill of material number | F4: מספר עץ מוצר | G4: PK | H4: • CSAP_MAT_BOM_CREATE • CSAP_MAT_BOM_MAINTAIN • CS_BT_BOM_HEADER_READ | I4: • יצירת עץ מוצר • תחזוקת עץ מוצר • קריאת כותרת עץ מוצר | J4: • RCSBI010 | K4: • פיצוץ עץ מוצר רב-רמתי | L4: ללא שינוי (תואם) | M4: STKO (זהה) | N4: CS01-03 / IB01; Fiori | O4: Manage Bills of Material (אמת ID) | P4: ללא פעולת המרה ייעודית ב-SUM (טבלה תואמת). מומלץ Regression Test ואימות התאמות אישיות לאחר ההמרה.
A5: 2 | D5: STLTY | E5: BOM category (E/T/M) | F5: קטגוריית BOM | G5: PK
A6: 3 | D6: STLAL | E6: Alternative BOM | F6: חלופת עץ מוצר | G6: PK
A7: 4 | D7: BMENG | E7: Base quantity | F7: כמות בסיס | G7: -
A8: 5 | D8: STLST | E8: BOM status | F8: סטטוס עץ מוצר | G8: -
A10: ◆ טבלה STPO - פריטי עץ מוצר (רכיבים) (BOM item (components))
A11: 6 | B11: IB02/CS02; CS11, CS15 | C11: STPO | D11: STLNR | E11: BOM number | F11: מספר עץ מוצר | G11: PK | H11: • CSAP_BOM_ITEM_MAINTAIN • CS_BOM_EXPL_MAT_RC1 | I11: • תחזוקת פריטי עץ מוצר • פיצוץ עץ מוצר לחומר | J11: • RCSBI010 • CS_BT | K11: • פיצוץ רב-רמתי • דוח Where-Used לרכיב | L11: ללא שינוי (תואם) | M11: STPO (זהה) | N11: CS0*; Fiori | O11: Manage Bills of Material (אמת ID) | P11: ללא פעולת המרה ייעודית ב-SUM (טבלה תואמת). מומלץ Regression Test ואימות התאמות אישיות לאחר ההמרה.
A12: 7 | D12: POSNR | E12: BOM item number | F12: מספר פריט | G12: PK
A13: 8 | D13: IDNRK | E13: Component (BOM item material) | F13: רכיב / חומר | G13: FK
A14: 9 | D14: MENGE | E14: Component quantity | F14: כמות רכיב | G14: -
A15: 10 | D15: POSTP | E15: Item category | F15: סוג פריט | G15: -
A17: ◆ טבלה MAST - קישור חומר לעץ מוצר (Material-to-BOM link)
A18: 11 | B18: CS01; CS02/CS03 | C18: MAST | D18: MATNR | E18: Material number | F18: חומר | G18: PK/FK | H18: • CSAP_MAT_BOM_READ | I18: • קריאת קישור חומר-BOM | J18: • RCSBI010 | K18: • פיצוץ עץ מוצר לחומר | L18: ללא שינוי (תואם) | M18: MAST (זהה) | N18: CS0*; Fiori | O18: Manage Bills of Material (אמת ID) | P18: ללא פעולת המרה ייעודית ב-SUM (טבלה תואמת). מומלץ Regression Test ואימות התאמות אישיות לאחר ההמרה.
A19: 12 | D19: WERKS | E19: Plant | F19: מפעל | G19: PK
A20: 13 | D20: STLAN | E20: BOM usage (4=maintenance) | F20: שימוש עץ מוצר | G20: PK
A21: 14 | D21: STLNR | E21: BOM number | F21: מספר עץ מוצר | G21: PK/FK
A22: 15 | D22: STLAL | E22: Alternative BOM | F22: חלופה | G22: -
A24: ◆ טבלה EQST - קישור ציוד לעץ מוצר (Equipment-to-BOM link)
A25: 16 | B25: IB01; IB02/IB03 | C25: EQST | D25: EQUNR | E25: Equipment number | F25: מספר ציוד | G25: PK/FK | H25: • CS_BOM_EXPL_EQU_RC1 | I25: • פיצוץ עץ מוצר של ציוד | J25: • RCSBI010 | K25: • פיצוץ עץ מוצר של ציוד | L25: ללא שינוי (תואם) | M25: EQST (זהה) | N25: IB01-03; Fiori | O25: Manage Bills of Material (אמת ID) | P25: ללא פעולת המרה ייעודית ב-SUM (טבלה תואמת). מומלץ Regression Test ואימות התאמות אישיות לאחר ההמרה.
A26: 17 | D26: STLNR | E26: BOM number | F26: מספר עץ מוצר | G26: FK
A27: 18 | D27: STLAL | E27: Alternative BOM | F27: חלופה | G27: PK
A28: 19 | D28: STLAN | E28: BOM usage | F28: שימוש עץ מוצר | G28: -
A30: ◆ טבלה TPST - קישור מיקום פונקציונלי לעץ מוצר (Functional location-to-BOM link)
A31: 20 | B31: IB11; IB12/IB13 | C31: TPST | D31: TPLNR | E31: Functional location | F31: מיקום פונקציונלי | G31: PK/FK | H31: • CS_BOM_EXPL_FLO_RC1 | I31: • פיצוץ עץ מוצר של מיקום | J31: • RCSBI020 | K31: • פיצוץ עצי מוצר של מיקומים | L31: ללא שינוי (תואם) | M31: TPST (זהה) | N31: IB11-13; Fiori | O31: Manage Bills of Material (אמת ID) | P31: ללא פעולת המרה ייעודית ב-SUM (טבלה תואמת). מומלץ Regression Test ואימות התאמות אישיות לאחר ההמרה.
A32: 21 | D32: STLNR | E32: BOM number | F32: מספר עץ מוצר | G32: FK
A33: 22 | D33: STLAL | E33: Alternative BOM | F33: חלופה | G33: PK
A34: 23 | D34: STLAN | E34: BOM usage | F34: שימוש עץ מוצר | G34: -
A37: ⚙ הרחבות טכניות ושינויי ארכיטקטורה (Technical Extensions: User Exits / BAdIs / ECC vs S/4HANA)
A38: סוג (Type) | C38: קוד / שם טכני (Code) | E38: תיאור / הבדל (Hebrew)
A39: User Exit (SMOD) | C39: PCSD0001 | E39: הרחבת לקוח לעצי מוצר (BOM) - בדיקות פריטים
A40: User Exit (SMOD) | C40: PCSD0002 | E40: ברירות מחדל לפריטי עץ מוצר
A41: BAdI (SE18) | C41: BOM_UPDATE | E41: BAdI לעדכון/בדיקת עצי מוצר (אמת ב-SE18)
A42: BAdI (SE18) | C42: BADI_EAM_TECHNICAL_OBJECT | E42: שיוך BOM לאובייקט טכני ב-S/4
A43: ארכיטקטורה ECC↔S/4 | C43: — | E43: מבני STKO/STPO/MAST/EQST/TPST ללא שינוי; שימוש עץ מוצר 4 (אחזקה) נשמר.
A44: ארכיטקטורה ECC↔S/4 | C44: — | E44: ב-S/4 ניהול BOM גם דרך Fiori; הארכת אורך חומר משפיעה על IDNRK.

Sheet 4. נקודות מדידה ומונים
A1: ◄ חזרה למסך הראשי | C1: 4. נקודות מדידה ומונים | ECC 6.0 ➜ S/4HANA · CBC NEO
A2: מס' (#) | B2: טרנזקציות ECC (Main & Secondary) | C2: טבלת בסיס (Core Table) | D2: שדה טכני (Field) | E2: Field (English) | F2: שדה (עברית) | G2: סוג מפתח (Key Type) | H2: פונקציות / BAPIs | I2: תיאור הפונקציה | J2: תוכניות / דוחות | K2: תיאור התוכנית | L2: סטטוס S/4HANA | M2: טבלה/שדה חלופי ב-S/4 | N2: טרנז'/תוכנית מחליפה ב-S/4 | O2: אפליקציית Fiori (שם + ID) | P2: שלב מיגרציה / הערות SUM Conversion
A3: ◆ טבלה IMPTT - רשומת אב של נקודת מדידה / מונה (Measuring point master)
A4: 1 | B4: IK01/IK02/IK03; IK07, IK08 | C4: IMPTT | D4: POINT | E4: Measuring point number | F4: מספר נקודת מדידה | G4: PK | H4: • BAPI_MEASUREMENTPOINT_CREATE • BAPI_MEASUREMENTPOINT_GETLIST • MEASUREMENT_POINT_READ | I4: • יצירת נקודת מדידה • שליפת רשימת נקודות מדידה • קריאת פרטי נקודת מדידה | J4: • RIMPOINT | K4: • רשימת נקודות מדידה ומונים | L4: ללא שינוי (תואם) | M4: IMPTT (זהה) | N4: IK01-03; Fiori | O4: Manage Measurement Documents (אמת ID) | P4: ללא פעולת המרה ייעודית ב-SUM (טבלה תואמת). מומלץ Regression Test ואימות התאמות אישיות לאחר ההמרה.
A5: 2 | D5: MPOBJ | E5: Measuring object (eq./FL) | F5: אובייקט מדידה | G5: FK
A6: 3 | D6: MPTYP | E6: Measuring point category | F6: סוג נקודת מדידה | G6: -
A7: 4 | D7: ATINN | E7: Internal characteristic | F7: מאפיין סיווג פנימי | G7: FK
A8: 5 | D8: INDCT | E8: Counter direction indicator | F8: קוד כיוון מונה | G8: -
A9: 6 | D9: DECIM | E9: Decimal places | F9: ספרות עשרוניות | G9: -
A11: ◆ טבלה IMRG - מסמכי מדידה (קריאות מונה/ערך) (Measurement documents / readings)
A12: 7 | B12: IK11/IK12/IK13; IK21, IK41 | C12: IMRG | D12: MDOCM | E12: Measurement document number | F12: מספר מסמך מדידה | G12: PK | H12: • BAPI_MEASUREMENTDOCUM_CREATE • BAPI_MEASUREMENTDOCUM_CREATEM • MEASUREM_DOCUM_RFC_SINGLE_001 | I12: • יצירת מסמך מדידה • יצירת מסמכי מדידה מרובים • קליטת קריאה בודדת RFC | J12: • RISTRA20 | K12: • ניטור מועדים מבוסס מונה (IP30) | L12: ללא שינוי (תואם) | M12: IMRG (זהה) | N12: IK11-13; Fiori | O12: Enter Measurement Readings (אמת ID) | P12: ללא פעולת המרה ייעודית ב-SUM (טבלה תואמת). מומלץ Regression Test ואימות התאמות אישיות לאחר ההמרה.
A13: 8 | D13: POINT | E13: Measuring point | F13: נקודת מדידה | G13: FK
A14: 9 | D14: RECDV | E14: Measurement reading value | F14: ערך נמדד | G14: -
A15: 10 | D15: READG | E15: Counter reading | F15: קריאת מונה | G15: -
A16: 11 | D16: CNTRR | E16: Counter reading (total) | F16: קריאה כוללת | G16: -
A17: 12 | D17: CDIFF | E17: Counter difference | F17: הפרש מונה | G17: -
A20: ⚙ הרחבות טכניות ושינויי ארכיטקטורה (Technical Extensions: User Exits / BAdIs / ECC vs S/4HANA)
A21: סוג (Type) | C21: קוד / שם טכני (Code) | E21: תיאור / הבדל (Hebrew)
A22: User Exit (SMOD) | C22: IMRC0001 | E22: הרחבת בדיקות בעת קליטת מסמך מדידה
A23: User Exit (SMOD) | C23: IMRC0002 | E23: לוגיקת העברת קריאות ומונים
A24: BAdI (SE18) | C24: BADI_EAM_MEASPOINT | E24: הרחבת נקודות מדידה/מסמכי מדידה (אמת שם ב-SE18)
A25: ארכיטקטורה ECC↔S/4 | C25: — | E25: IMPTT/IMRG ללא שינוי; לוגיקת גלישת מונה נשמרת.
A26: ארכיטקטורה ECC↔S/4 | C26: — | E26: ב-S/4 קליטת קריאות אוטומטית דרך IoT/Asset Central ו-Fiori 'Enter Measurement Readings'.

Sheet 5. קטלוגים, קודים ופרופילים
A1: ◄ חזרה למסך הראשי | C1: 5. קטלוגים, קודים ופרופילים | ECC 6.0 ➜ S/4HANA · CBC NEO
A2: מס' (#) | B2: טרנזקציות ECC (Main & Secondary) | C2: טבלת בסיס (Core Table) | D2: שדה טכני (Field) | E2: Field (English) | F2: שדה (עברית) | G2: סוג מפתח (Key Type) | H2: פונקציות / BAPIs | I2: תיאור הפונקציה | J2: תוכניות / דוחות | K2: תיאור התוכנית | L2: סטטוס S/4HANA | M2: טבלה/שדה חלופי ב-S/4 | N2: טרנז'/תוכנית מחליפה ב-S/4 | O2: אפליקציית Fiori (שם + ID) | P2: שלב מיגרציה / הערות SUM Conversion
A3: ◆ טבלה QPCD - קודים בתוך קבוצת קוד (Codes within a code group)
A4: 1 | B4: QS51; QS61 | C4: QPCD | D4: KATALOGART | E4: Catalog type (B/C/D/2/5) | F4: סוג קטלוג | G4: PK | H4: • QPK1_CODE_TEXT_READ • QPK1_CATALOG_READ | I4: • קריאת קוד וטקסט • קריאת קטלוג | J4: • RQEEAW01 | K4: • סקירת מבנה קטלוגים | L4: ללא שינוי (Customizing/Master תואם) | M4: QPCD (זהה) | N4: QS41/QS51 (זהה) | O4: אין Fiori ייעודי (Customizing) | P4: ללא פעולת המרה ייעודית ב-SUM (טבלה תואמת). מומלץ Regression Test ואימות התאמות אישיות לאחר ההמרה.
A5: 2 | D5: CODEGRUPPE | E5: Code group | F5: קבוצת קוד | G5: PK
A6: 3 | D6: CODE | E6: Code | F6: קוד | G6: PK
A7: 4 | D7: VERSION | E7: Code version | F7: גרסת קוד | G7: PK
A9: ◆ טבלה QPGR - קבוצות קוד (במקום QPCR הלא-תקני) (Code groups (correct table))
A10: 5 | B10: QS51; QS61 | C10: QPGR | D10: KATALOGART | E10: Catalog type | F10: סוג קטלוג | G10: PK | H10: • QPK1_CODEGROUP_READ | I10: • קריאת קבוצת קוד | J10: • RQEEAW02 | K10: • דוח קבוצות קוד וקודים | L10: ללא שינוי (תואם) | M10: QPGR (זהה) | N10: QS51 (זהה) | O10: אין Fiori ייעודי (Customizing) | P10: ללא פעולת המרה ייעודית ב-SUM (טבלה תואמת). מומלץ Regression Test ואימות התאמות אישיות לאחר ההמרה.
A11: 6 | D11: CODEGRUPPE | E11: Code group | F11: קבוצת קוד | G11: PK
A12: 7 | D12: STATUS | E12: Code group status | F12: סטטוס קבוצה | G12: -
A13: 8 | D13: VERWMERKM | E13: Selection set usage | F13: שימוש בקבוצת בחירה | G13: -
A15: ◆ טבלה T352B - שיוך פרופיל קטלוג לקבוצות בחירה (Catalog profile to selection-set link)
A16: 9 | B16: OIM1; OIN4 | C16: T352B | D16: RBNR | E16: Catalog profile | F16: פרופיל קטלוג | G16: PK | H16: • CATALOG_PROFILE_READ | I16: • קריאת פרופיל קטלוג | J16: • RIPROFCAT | K16: • ניתוח פרופילי קטלוג ושיוכם | L16: ללא שינוי (Customizing תואם) | M16: T352B (זהה) | N16: SPRO (זהה) | O16: אין Fiori ייעודי (Customizing) | P16: ללא פעולת המרה ייעודית ב-SUM (טבלה תואמת). מומלץ Regression Test ואימות התאמות אישיות לאחר ההמרה.
A17: 10 | D17: KATALOGART | E17: Catalog type | F17: סוג קטלוג | G17: PK
A18: 11 | D18: CODEGRUPPE | E18: Allowed code group | F18: קבוצת קוד מותרת | G18: FK
A19: 12 | D19: AUSWMENGEN | E19: Selection set | F19: קבוצת בחירה | G19: -
A21: ◆ טבלה T352 - פרופיל קטלוג (כותרת) (Catalog profile header)
A22: 13 | B22: OIM1; QCC0 | C22: T352 | D22: RBNR | E22: Catalog profile | F22: פרופיל קטלוג | G22: PK | H22: • T352_READ | I22: • קריאת פרופיל קטלוג | J22: • RIPROFCAT | K22: • ניתוח פרופילי קטלוג | L22: ללא שינוי (Customizing תואם) | M22: T352 (זהה) | N22: SPRO (זהה) | O22: אין Fiori ייעודי (Customizing) | P22: ללא פעולת המרה ייעודית ב-SUM (טבלה תואמת). מומלץ Regression Test ואימות התאמות אישיות לאחר ההמרה.
A23: 14 | D23: HERKZ | E23: Origin indicator | F23: מחוון מקור | G23: -
A24: 15 | D24: RBNRX | E24: Profile description | F24: תיאור פרופיל | G24: -
A27: ⚙ הרחבות טכניות ושינויי ארכיטקטורה (Technical Extensions: User Exits / BAdIs / ECC vs S/4HANA)
A28: סוג (Type) | C28: קוד / שם טכני (Code) | E28: תיאור / הבדל (Hebrew)
A29: User Exit (SMOD) | C29: QQMA0001 | E29: בדיקות כלליות בקטלוגים/קודים (משותף QM-PM)
A30: BAdI (SE18) | C30: BADI_CATALOG | E30: הרחבת לוגיקת קטלוגים (אמת שם ב-SE18)
A31: ארכיטקטורה ECC↔S/4 | C31: — | E31: קטלוגים, קבוצות קוד ופרופילי קטלוג (T352/T352B) ללא שינוי מבני.
A32: ארכיטקטורה ECC↔S/4 | C32: — | E32: ב-S/4 הקונפיגורציה זהה; ניהול דרך SPRO.

Sheet 6. הודעות אחזקה (Notifications)
A1: ◄ חזרה למסך הראשי | C1: 6. הודעות אחזקה (Notifications) | ECC 6.0 ➜ S/4HANA · CBC NEO
A2: מס' (#) | B2: טרנזקציות ECC (Main & Secondary) | C2: טבלת בסיס (Core Table) | D2: שדה טכני (Field) | E2: Field (English) | F2: שדה (עברית) | G2: סוג מפתח (Key Type) | H2: פונקציות / BAPIs | I2: תיאור הפונקציה | J2: תוכניות / דוחות | K2: תיאור התוכנית | L2: סטטוס S/4HANA | M2: טבלה/שדה חלופי ב-S/4 | N2: טרנז'/תוכנית מחליפה ב-S/4 | O2: אפליקציית Fiori (שם + ID) | P2: שלב מיגרציה / הערות SUM Conversion
A3: ◆ טבלה QMEL - כותרת הודעת אחזקה (Notification header)
A4: 1 | B4: IW21/IW22/IW23; IW24, IW28/IW29 | C4: QMEL | D4: QMNUM | E4: Notification number | F4: מספר הודעה | G4: PK | H4: • BAPI_ALM_NOTIF_CREATE • BAPI_ALM_NOTIF_DATA_ADD • BAPI_ALM_NOTIF_SAVE • BAPI_ALM_NOTIF_CLOSE • BAPI_ALM_NOTIF_GET_DETAIL | I4: • יצירת הודעה דרך ממשק תקני • הוספת פריט/סיבה/פעילות • שמירת ההודעה • סגירת ההודעה • שליפת פרטי הודעה מלאים | J4: • RIQMEL20 • RIQMEL00 | K4: • רשימת הודעות (IW28/29) • ניתוח דפוסי כשל | L4: ללא שינוי במודל הנתונים (תואם) | M4: QMEL (זהה) | N4: IW21-23 נתמכים; אסטרטגי: Fiori | O4: Report Malfunction (F2215) | P4: ללא פעולת המרה ייעודית ב-SUM (טבלה תואמת). מומלץ Regression Test ואימות התאמות אישיות לאחר ההמרה.
A5: 2 | D5: QMART | E5: Notification type (M1/M2/M3) | F5: סוג הודעה | G5: FK
A6: 3 | D6: QMTXT | E6: Notification short text | F6: תיאור קצר | G6: -
A7: 4 | D7: EQUNR | E7: Reference equipment | F7: ציוד מתייחס | G7: FK
A8: 5 | D8: TPLNR | E8: Reference functional location | F8: מיקום מתייחס | G8: FK
A9: 6 | D9: OBJNR | E9: Object number (status) | F9: מפתח אובייקט לסטטוס | G9: FK
A11: ◆ טבלה QMFE - פריטי הודעה (ליקויים) (Notification items (damage))
A12: 7 | B12: IW22; IW66 | C12: QMFE | D12: QMNUM | E12: Notification number | F12: מספר הודעה | G12: PK/FK | H12: • BAPI_ALM_NOTIF_DATA_ADD • NOTIF_ITEM_READ | I12: • הוספת פריט ליקוי • קריאת פריטי הודעה | J12: • RIQMEL00 | K12: • ניתוח פריטי ליקוי ודפוסי כשל | L12: ללא שינוי (תואם) | M12: QMFE (זהה) | N12: IW22; Fiori | O12: Find Maintenance Notification (אמת ID) | P12: ללא פעולת המרה ייעודית ב-SUM (טבלה תואמת). מומלץ Regression Test ואימות התאמות אישיות לאחר ההמרה.
A13: 8 | D13: FENUM | E13: Item number | F13: מספר פריט | G13: PK
A14: 9 | D14: FEGRP | E14: Damage code group | F14: קבוצת קוד ליקוי | G14: -
A15: 10 | D15: FECOD | E15: Damage code | F15: קוד ליקוי | G15: -
A16: 11 | D16: OTGRP | E16: Object part code group | F16: קבוצת אובייקט חלקי | G16: -
A17: 12 | D17: OTEIL | E17: Object part code | F17: קוד אובייקט חלקי | G17: -
A19: ◆ טבלה QMUR - סיבות לליקוי (Notification causes)
A20: 13 | B20: IW22; IW67 | C20: QMUR | D20: QMNUM | E20: Notification number | F20: מספר הודעה | G20: PK/FK | H20: • NOTIF_CAUSE_READ | I20: • קריאת סיבות הליקוי | J20: • RIQMUR00 | K20: • דוח סיבות לניתוח שורש (RCA) | L20: ללא שינוי (תואם) | M20: QMUR (זהה) | N20: IW22; Fiori | O20: Find Maintenance Notification (אמת ID) | P20: ללא פעולת המרה ייעודית ב-SUM (טבלה תואמת). מומלץ Regression Test ואימות התאמות אישיות לאחר ההמרה.
A21: 14 | D21: FENUM | E21: Item number | F21: מספר פריט | G21: PK/FK
A22: 15 | D22: URNUM | E22: Cause number | F22: מספר סיבה | G22: PK
A23: 16 | D23: URGRP | E23: Cause code group | F23: קבוצת קוד סיבה | G23: -
A24: 17 | D24: URCOD | E24: Cause code | F24: קוד סיבה | G24: -
A26: ◆ טבלה QMMA - פעילויות שבוצעו (במקום QMAA הלא-תקני) (Notification activities (correct table))
A27: 18 | B27: IW22; IW67 | C27: QMMA | D27: QMNUM | E27: Notification number | F27: מספר הודעה | G27: PK/FK | H27: • NOTIF_ACTIVITY_READ | I27: • קריאת פעילויות שבוצעו | J27: • RIQMEL00 | K27: • ניתוח פעילויות הודעה | L27: ללא שינוי (תואם) | M27: QMMA (זהה) | N27: IW22; Fiori | O27: Report Malfunction (F2215) | P27: ללא פעולת המרה ייעודית ב-SUM (טבלה תואמת). מומלץ Regression Test ואימות התאמות אישיות לאחר ההמרה.
A28: 19 | D28: MANUM | E28: Activity number | F28: מספר פעילות | G28: PK
A29: 20 | D29: MNGRP | E29: Activity code group | F29: קבוצת קוד פעילות | G29: -
A30: 21 | D30: MNCOD | E30: Activity code | F30: קוד פעילות | G30: -
A32: ◆ טבלה QMSM - משימות לטיפול (במקום QMAS הלא-תקני) (Notification tasks (correct table))
A33: 22 | B33: IW22; IW66 | C33: QMSM | D33: QMNUM | E33: Notification number | F33: מספר הודעה | G33: PK/FK | H33: • NOTIF_TASK_READ • BAPI_ALM_NOTIF_TASK_ADD | I33: • קריאת משימות • הוספת משימה | J33: • RIQMEL20 | K33: • מעקב משימות פתוחות | L33: ללא שינוי (תואם) | M33: QMSM (זהה) | N33: IW22; Fiori | O33: Find Maintenance Notification (אמת ID) | P33: ללא פעולת המרה ייעודית ב-SUM (טבלה תואמת). מומלץ Regression Test ואימות התאמות אישיות לאחר ההמרה.
A34: 23 | D34: MANUM | E34: Task number | F34: מספר משימה | G34: PK
A35: 24 | D35: MNGRP | E35: Task code group | F35: קבוצת קוד משימה | G35: -
A36: 25 | D36: MNCOD | E36: Task code | F36: קוד משימה | G36: -
A37: 26 | D37: PSTER | E37: Task planned completion | F37: מועד יעד למשימה | G37: -
A39: ◆ טבלה TQ80 - סוגי הודעה (Notification Types - Customizing; הוגדר כ-T356, ש=עדיפויות) (Notification types (config; correct=TQ80, T356=Priorities))
A40: 27 | B40: OIAL (פריסת מסך); SPRO, QCC0 | C40: TQ80 | D40: QMART | E40: Notification type (M1/M2/M3) | F40: סוג הודעה | G40: PK | H40: • PM_NOTIFICATION_TYPE_READ • PRIORITY_DETERMINE | I40: • קריאת סוג הודעה והגדרותיו • קביעת עדיפות לפי סוג | J40: • RIQMEL20 | K40: • ניתוח הודעות לפי סוג | L40: ללא שינוי (Customizing תואם) | M40: TQ80 (זהה) | N40: SPRO/OIAL (זהה) | O40: אין Fiori ייעודי (Customizing) | P40: ללא פעולת המרה ייעודית ב-SUM (טבלה תואמת). מומלץ Regression Test ואימות התאמות אישיות לאחר ההמרה.
A41: 28 | D41: QMTYP | E41: Notification category | F41: קטגוריית הודעה | G41: -
A42: 29 | D42: RBNR | E42: Catalog profile | F42: פרופיל קטלוג | G42: FK
A43: 30 | D43: AUART | E43: Default order type | F43: סוג פק"ע ברירת מחדל | G43: FK
A46: ⚙ הרחבות טכניות ושינויי ארכיטקטורה (Technical Extensions: User Exits / BAdIs / ECC vs S/4HANA)
A47: סוג (Type) | C47: קוד / שם טכני (Code) | E47: תיאור / הבדל (Hebrew)
...

Sheet 7. פקודות עבודה (פק"ע)
A1: ◄ חזרה למסך הראשי | C1: 7. פקודות עבודה (פק"ע) | ECC 6.0 ➜ S/4HANA · CBC NEO
A2: מס' (#) | B2: טרנזקציות ECC (Main & Secondary) | C2: טבלת בסיס (Core Table) | D2: שדה טכני (Field) | E2: Field (English) | F2: שדה (עברית) | G2: סוג מפתח (Key Type) | H2: פונקציות / BAPIs | I2: תיאור הפונקציה | J2: תוכניות / דוחות | K2: תיאור התוכנית | L2: סטטוס S/4HANA | M2: טבלה/שדה חלופי ב-S/4 | N2: טרנז'/תוכנית מחליפה ב-S/4 | O2: אפליקציית Fiori (שם + ID) | P2: שלב מיגרציה / הערות SUM Conversion
A3: ◆ טבלה AUFK - נתוני אב של פקודת עבודה (Order master data)
A4: 1 | B4: IW31/IW32/IW33; IW34, IW38/IW39 | C4: AUFK | D4: AUFNR | E4: Order number | F4: מספר פק"ע | G4: PK | H4: • BAPI_ALM_ORDER_MAINTAIN • BAPI_ALM_ORDER_GET_DETAIL • BAPI_ALM_ORDERHEAD_GET_LIST | I4: • יצירה/שינוי פק"ע (ממשק מרכזי) • שליפת פרטי פק"ע • שליפת רשימת פק"ע | J4: • RIAUFK20 | K4: • רשימת פק"ע (IW38/39) | L4: מותאם - מודל נתונים פשוט יותר לפקודות | M4: AUFK (זהה) + סטטוס/עלות ב-ACDOCA | N4: IW31-33 נתמכים; אסטרטגי: Fiori | O4: Find Maintenance Order (F2393) | P4: עלויות מומרות ל-Universal Journal (ACDOCA) ב-SUM. COSP/COSS הופכים ל-Views. התאם דוחות עלות מותאמים והרצות התחשבנות.
A5: 2 | D5: AUART | E5: Order type (PM01/02/03) | F5: סוג פק"ע | G5: FK
A6: 3 | D6: KTEXT | E6: Order short text | F6: תיאור הפק"ע | G6: -
A7: 4 | D7: OBJNR | E7: Object number (status/CO) | F7: מפתח אובייקט | G7: FK
A8: 5 | D8: KOSTV | E8: Responsible cost center | F8: מרכז עלות אחראי | G8: FK
A10: ◆ טבלה AFKO - כותרת פקודה (נתוני אחזקה/ייצור) (Order header data)
A11: 6 | B11: IW32; IW37N | C11: AFKO | D11: AUFNR | E11: Order number | F11: מספר פק"ע | G11: PK/FK | H11: • CO_ZF_ORDER_HEADER_READ | I11: • קריאת כותרת הפקודה | J11: • RIAUFK20 | K11: • רשימת פק"ע | L11: מותאם (תואם עם פישוטי תזמון) | M11: AFKO (זהה) | N11: IW32; Fiori | O11: Create Maintenance Order (אמת ID) | P11: אין המרת טבלה הרסנית, אך מודל הנתונים מותאם - הרץ Regression Test ובדוק User Exits/דוחות מותאמים.
A12: 7 | D12: AUFPL | E12: Routing/operation plan number | F12: מספר תוכנית פעולות | G12: FK
A13: 8 | D13: GLTRP | E13: Basic finish date | F13: תאריך סיום בסיסי | G13: -
A14: 9 | D14: GSTRP | E14: Basic start date | F14: תאריך התחלה בסיסי | G14: -
A15: 10 | D15: PLNBEZ | E15: BOM/material reference | F15: הפניית עץ מוצר/חומר | G15: FK
A17: ◆ טבלה AFVC - פעולות הפקודה (Operations - השם התקני; לא AFVG) (Order operations (correct table name, not AFVG))
A18: 11 | B18: IW31/IW32/IW33; IW37N, CM01 | C18: AFVC | D18: AUFPL | E18: Routing/operations plan no. - joins AFKO | F18: מספר תוכנית פעולות - מצטרף ל-AFKO | G18: PK/FK | H18: • BAPI_ALM_ORDER_MAINTAIN • CO_ZF_OPERATIONS_READ | I18: • הוספת/שינוי פעולות בפק"ע (METHOD=OPERATION) • קריאת פעולות הפקודה | J18: • RIAFVC00 | K18: • ניתוח פעולות ועומסי קיבולת | L18: מותאם (תואם) | M18: AFVC (זהה) | N18: IW32; Fiori Operations | O18: Find Maintenance Order (F2393) | P18: אין המרת טבלה הרסנית, אך מודל הנתונים מותאם - הרץ Regression Test ובדוק User Exits/דוחות מותאמים.
A19: 12 | D19: APLZL | E19: Internal operation counter | F19: מונה פעולה פנימי | G19: PK
A20: 13 | D20: VORNR | E20: Operation number | F20: מספר פעולה | G20: -
A21: 14 | D21: ARBID | E21: Work center (object id) | F21: מרכז עבודה (מזהה אובייקט) | G21: FK
A22: 15 | D22: STEUS | E22: Control key (in-house/external) | F22: מפתח בקרה (פנימי/חיצוני) | G22: -
A23: 16 | D23: LTXA1 | E23: Operation short text | F23: תיאור קצר של הפעולה | G23: -
A25: ◆ טבלה AFPO - פריט פקודה (Order item)
A26: 17 | B26: IW32; IW33 | C26: AFPO | D26: AUFNR | E26: Order number | F26: מספר פק"ע | G26: PK/FK | H26: • CO_ZF_ORDER_ITEM_READ | I26: • קריאת פריט הפקודה | J26: • RIAFPO00 | K26: • ניתוח פריטי פקודה | L26: מותאם (תואם) | M26: AFPO (זהה) | N26: IW32; Fiori | O26: Find Maintenance Order (F2393) | P26: אין המרת טבלה הרסנית, אך מודל הנתונים מותאם - הרץ Regression Test ובדוק User Exits/דוחות מותאמים.
A27: 18 | D27: POSNR | E27: Order item number | F27: מספר פריט | G27: PK
A28: 19 | D28: MATNR | E28: Material (refurbishment) | F28: חומר (שיפוץ) | G28: FK
A29: 20 | D29: PSAMG | E29: Order item quantity | F29: כמות פריט | G29: -
A31: ◆ טבלה AFIH - כותרת פקודה - נתוני אחזקה (PM) (Maintenance order header (PM))
A32: 21 | B32: IW32; IW33 | C32: AFIH | D32: AUFNR | E32: Order number | F32: מספר פק"ע | G32: PK/FK | H32: • BAPI_ALM_ORDER_GET_DETAIL | I32: • שליפת נתוני אחזקה של הפק"ע | J32: • RIAUFK20 | K32: • רשימת פק"ע אחזקה | L32: מותאם (תואם) | M32: AFIH (זהה) | N32: IW32; Fiori | O32: Find Maintenance Order (F2393) | P32: אין המרת טבלה הרסנית, אך מודל הנתונים מותאם - הרץ Regression Test ובדוק User Exits/דוחות מותאמים.
A33: 22 | D33: EQUNR | E33: Reference equipment | F33: ציוד מתייחס | G33: FK
A34: 23 | D34: TPLNR | E34: Reference functional location | F34: מיקום מתייחס | G34: FK
A35: 24 | D35: ILART | E35: Maintenance activity type | F35: סוג פעילות אחזקה | G35: -
A36: 25 | D36: PRIOK | E36: Priority | F36: עדיפות | G36: -
A37: 26 | D37: GEWRK | E37: Main work center | F37: מרכז עבודה ראשי | G37: FK
A39: ◆ טבלה AFWI - תנועות מלאי המקושרות לדיווחי ביצוע (Goods movements for confirmations)
A40: 27 | B40: IW41; IW42 | C40: AFWI | D40: RUECK | E40: Confirmation counter | F40: מספר דיווח ביצוע | G40: PK/FK | H40: • BAPI_ALM_CONF_CREATE | I40: • יצירת דיווח ביצוע עם תנועות מלאי | J40: • RIAFRU00 | K40: • ניתוח דיווחי ביצוע ותנועות נלוות | L40: מותאם (תנועת מלאי ב-MATDOC) | M40: AFWI (זהה); מסמך חומר ב-MATDOC | N40: IW41/IW42; Fiori Confirmation | O40: Confirm Maintenance Order (אמת ID) | P40: המרה אוטומטית ל-MATDOC ב-SUM (Silent Data Migration). MKPF/MSEG הופכים ל-Compatibility Views. בדוק קוד Z שקורא ישירות ל-MSEG/MKPF ועדכן ל-CDS/MATDOC.
A41: 28 | D41: RMZHL | E41: Confirmation number | F41: מונה דיווח | G41: PK
A42: 29 | D42: MBLNR | E42: Material document number | F42: מסמך חומר | G42: FK
A43: 30 | D43: MATNR | E43: Material | F43: חומר | G43: FK
A45: ◆ טבלה T003O - סוגי פקודה (Order Types - Customizing; הוגדר כ-T350) (Order types (config; correct=T003O, not T350))
A46: 31 | B46: SPRO; OIOA, KOT2_OPA | C46: T003O | D46: AUART | E46: Order type (PM01/PM02/PM03) | F46: סוג פקודה | G46: PK | H46: • ORDER_TYPE_READ • CO_BT_ORDER_TYPE_CHECK | I46: • קריאת סוג פקודה והגדרותיו • בדיקת תקינות סוג פקודה | J46: • RIAUFK20 | K46: • ניתוח פק"ע לפי סוג | L46: ללא שינוי (Customizing תואם) | M46: T003O (זהה) | N46: SPRO/OIOA (זהה) | O46: אין Fiori ייעודי (Customizing) | P46: ללא פעולת המרה ייעודית ב-SUM (טבלה תואמת). מומלץ Regression Test ואימות התאמות אישיות לאחר ההמרה.
...

Sheet 8. ניהול סטטוסים (Status Mgmt)
A1: ◄ חזרה למסך הראשי | C1: 8. ניהול סטטוסים (Status Mgmt) | ECC 6.0 ➜ S/4HANA · CBC NEO
A2: מס' (#) | B2: טרנזקציות ECC (Main & Secondary) | C2: טבלת בסיס (Core Table) | D2: שדה טכני (Field) | E2: Field (English) | F2: שדה (עברית) | G2: סוג מפתח (Key Type) | H2: פונקציות / BAPIs | I2: תיאור הפונקציה | J2: תוכניות / דוחות | K2: תיאור התוכנית | L2: סטטוס S/4HANA | M2: טבלה/שדה חלופי ב-S/4 | N2: טרנז'/תוכנית מחליפה ב-S/4 | O2: אפליקציית Fiori (שם + ID) | P2: שלב מיגרציה / הערות SUM Conversion
A3: ◆ טבלה JEST - סטטוס אובייקט (פעיל/לא פעיל) (Individual object status)
A4: 1 | B4: BS22/BS23; IW33, IE03 | C4: JEST | D4: OBJNR | E4: Object number | F4: מפתח אובייקט | G4: PK/FK | H4: • STATUS_READ • STATUS_CHANGE_INTERN • STATUS_CHANGE_EXTERN | I4: • קריאת סטטוסי אובייקט • שינוי סטטוס מערכת פנימי • שינוי סטטוס משתמש | J4: • RISTAT00 | K4: • ניתוח סטטוסים פעילים לאובייקטים | L4: ללא שינוי (תואם) | M4: JEST (זהה) | N4: BS22/BS23 (זהה) | O4: מוטמע באפליקציות PM (אין ייעודי) | P4: ללא פעולת המרה ייעודית ב-SUM (טבלה תואמת). מומלץ Regression Test ואימות התאמות אישיות לאחר ההמרה.
A5: 2 | D5: STAT | E5: Status code | F5: קוד סטטוס | G5: PK
A6: 3 | D6: INACT | E6: Inactive indicator | F6: מחוון לא-פעיל | G6: -
A7: 4 | D7: CHGNR | E7: Change number | F7: מספר שינוי | G7: -
A9: ◆ טבלה JSTO - כותרת אובייקט סטטוס + פרופיל (Status object header + profile)
A10: 5 | B10: BS02/BS03; OIBS | C10: JSTO | D10: OBJNR | E10: Object number | F10: מפתח אובייקט | G10: PK | H10: • STATUS_OBJECT_CREATE • STATUS_PROFILE_READ | I10: • יצירת אובייקט סטטוס • קריאת פרופיל סטטוס | J10: • RIBS0200 | K10: • סקירת פרופילי סטטוס וחסימות | L10: ללא שינוי (תואם) | M10: JSTO (זהה) | N10: BS02/BS03 (זהה) | O10: מוטמע באפליקציות PM (אין ייעודי) | P10: ללא פעולת המרה ייעודית ב-SUM (טבלה תואמת). מומלץ Regression Test ואימות התאמות אישיות לאחר ההמרה.
A11: 6 | D11: STSMA | E11: Status profile | F11: פרופיל סטטוס | G11: FK
A12: 7 | D12: OBTYP | E12: Object type | F12: סוג אובייקט | G12: -
A13: 8 | D13: CHGKZ | E13: Change flag | F13: מחוון שינוי | G13: -
A15: ◆ טבלה TJ02T - טקסטים של סטטוסי מערכת (System status texts)
A16: 9 | B16: BS23; BS22 | C16: TJ02T | D16: ISTAT | E16: Internal system status | F16: סטטוס מערכת פנימי | G16: PK | H16: • STATUS_TEXT_READ | I16: • קריאת טקסט סטטוס מערכת | J16: • RISTAT00 | K16: • פענוח קודי סטטוס בדוחות | L16: ללא שינוי (תואם) | M16: TJ02T (זהה) | N16: BS23 (זהה) | O16: מוטמע (אין ייעודי) | P16: ללא פעולת המרה ייעודית ב-SUM (טבלה תואמת). מומלץ Regression Test ואימות התאמות אישיות לאחר ההמרה.
A17: 10 | D17: SPRAS | E17: Language key | F17: שפה | G17: PK
A18: 11 | D18: TXT04 | E18: Status code (CRTD/REL/TECO/CLSD) | F18: קוד סטטוס מקוצר | G18: -
A19: 12 | D19: TXT30 | E19: Status long text | F19: תיאור ארוך | G19: -
A21: ◆ טבלה TJ30T - טקסטים של סטטוסי משתמש (User status texts)
A22: 13 | B22: BS02; BS03 | C22: TJ30T | D22: STSMA | E22: Status profile | F22: פרופיל סטטוס | G22: PK | H22: • USER_STATUS_TEXT_READ | I22: • קריאת טקסט סטטוס משתמש | J22: • RIBS0200 | K22: • סקירת סטטוסי משתמש בפרופיל | L22: ללא שינוי (תואם) | M22: TJ30T (זהה) | N22: BS02/BS03 (זהה) | O22: מוטמע (אין ייעודי) | P22: ללא פעולת המרה ייעודית ב-SUM (טבלה תואמת). מומלץ Regression Test ואימות התאמות אישיות לאחר ההמרה.
A23: 14 | D23: ESTAT | E23: User status | F23: סטטוס משתמש | G23: PK
A24: 15 | D24: SPRAS | E24: Language key | F24: שפה | G24: PK
A25: 16 | D25: TXT04 | E25: User status short code | F25: קוד מקוצר | G25: -
A26: 17 | D26: TXT30 | E26: User status text | F26: תיאור סטטוס משתמש | G26: -
A28: ◆ טבלה TJ30 - סטטוסי משתמש בפרופיל (User Status - לתהליכי CBC) (User statuses within status profile (workflow control))
A29: 18 | B29: BS02/BS03; OIBS | C29: TJ30 | D29: STSMA | E29: Status profile | F29: פרופיל סטטוס | G29: PK/FK | H29: • STATUS_USER_CHANGE • STATUS_PROFILE_READ | I29: • שינוי סטטוס משתמש • קריאת פרופיל וסטטוסי המשתמש | J29: • RIBS0200 | K29: • סקירת פרופילי סטטוס וחסימות תהליך | L29: ללא שינוי (תואם) | M29: TJ30 (זהה) | N29: BS02/BS03 (זהה) | O29: מוטמע באפליקציות PM (אין ייעודי) | P29: ללא פעולת המרה ייעודית ב-SUM (טבלה תואמת). מומלץ Regression Test ואימות התאמות אישיות לאחר ההמרה.
A30: 19 | D30: ESTAT | E30: User status | F30: סטטוס משתמש | G30: PK
A31: 20 | D31: TXT04 | E31: User status short code | F31: קוד מקוצר | G31: -
A32: 21 | D32: ANWND | E32: Application (PM=order/notif.) | F32: יישום (PM) | G32: -
A33: 22 | D33: VORNR | E33: Status sequence number | F33: מספר סדר סטטוס | G33: -
A36: ⚙ הרחבות טכניות ושינויי ארכיטקטורה (Technical Extensions: User Exits / BAdIs / ECC vs S/4HANA)
A37: סוג (Type) | C37: קוד / שם טכני (Code) | E37: תיאור / הבדל (Hebrew)
A38: User Exit (SMOD) | C38: STATUS (BS02/BS22) | E38: סטטוס משתמש מוגדר בפרופיל ולא דרך user-exit ייעודי
A39: BAdI (SE18) | C39: BADI_STATUS_MANAGEMENT | E39: הרחבת לוגיקת סטטוס (אמת שם ב-SE18)
A40: ארכיטקטורה ECC↔S/4 | C40: — | E40: JEST/JSTO/TJ02T/TJ30T ללא שינוי; חוקי החסימה (כגון GI לפני REL) זהים.
A41: ארכיטקטורה ECC↔S/4 | C41: — | E41: ב-S/4 ניהול סטטוס מוטמע באפליקציות Fiori של האובייקט.

Sheet 9. אינטגרציית מלאי ורכש (PM-MM)
A1: ◄ חזרה למסך הראשי | C1: 9. אינטגרציית מלאי ורכש (PM-MM) | ECC 6.0 ➜ S/4HANA · CBC NEO
A2: מס' (#) | B2: טרנזקציות ECC (Main & Secondary) | C2: טבלת בסיס (Core Table) | D2: שדה טכני (Field) | E2: Field (English) | F2: שדה (עברית) | G2: סוג מפתח (Key Type) | H2: פונקציות / BAPIs | I2: תיאור הפונקציה | J2: תוכניות / דוחות | K2: תיאור התוכנית | L2: סטטוס S/4HANA | M2: טבלה/שדה חלופי ב-S/4 | N2: טרנז'/תוכנית מחליפה ב-S/4 | O2: אפליקציית Fiori (שם + ID) | P2: שלב מיגרציה / הערות SUM Conversion
A3: ◆ טבלה RESB - הזמנת רכיבים (Reservation) (Reservation / dependent requirements)
A4: 1 | B4: MB1A/MIGO; MB21, IW32 | C4: RESB | D4: RSNUM | E4: Reservation number | F4: מספר הזמנה | G4: PK | H4: • BAPI_RESERVATION_CREATE1 • BAPI_GOODSMVT_CREATE • RESERVATION_READ | I4: • יצירת הזמנת מלאי • רישום פליטת חומר (261) • קריאת הזמנת רכיבים | J4: • RM07RESL | K4: • דוח הזמנות מלאי פתוחות | L4: ללא שינוי (תואם) | M4: RESB (זהה) | N4: MIGO/MB1A נתמכים; Fiori | O4: Post Goods Movement / MIGO (אמת ID) | P4: ללא פעולת המרה ייעודית ב-SUM (טבלה תואמת). מומלץ Regression Test ואימות התאמות אישיות לאחר ההמרה.
A5: 2 | D5: RSPOS | E5: Reservation item | F5: פריט הזמנה | G5: PK
A6: 3 | D6: MATNR | E6: Component material | F6: חומר רכיב | G6: FK
A7: 4 | D7: BDMNG | E7: Requirement quantity | F7: כמות נדרשת | G7: -
A8: 5 | D8: ENMNG | E8: Quantity withdrawn | F8: כמות שנפלטה | G8: -
A9: 6 | D9: AUFNR | E9: Order (account assignment) | F9: פק"ע מחויבת | G9: FK
A11: ◆ טבלה EBAN - דרישת רכש (Purchase Requisition) (Purchase requisition)
A12: 7 | B12: ME51N; ME52N/ME53N, ME57 | C12: EBAN | D12: BANFN | E12: Purchase requisition number | F12: מספר דרישת רכש | G12: PK | H12: • BAPI_PR_CREATE • BAPI_REQUISITION_GETDETAIL | I12: • יצירת דרישת רכש • שליפת פרטי דרישת רכש | J12: • RM06BANF | K12: • דוח דרישות רכש פתוחות | L12: מותאם (Business Partner לספקים) | M12: EBAN (זהה) | N12: ME51N נתמך; ספק דרך BP | O12: Manage Purchase Requisitions (אמת ID) | P12: נדרש CVI והמרת ספקים/לקוחות ל-Business Partner לפני/במהלך ההמרה (Pre-check חובה).
A13: 8 | D13: BNFPO | E13: Requisition item | F13: פריט דרישה | G13: PK
A14: 9 | D14: MATNR | E14: Material | F14: חומר | G14: FK
A15: 10 | D15: KNTTP | E15: Account assignment cat. (F=order) | F15: סוג חיוב | G15: -
A16: 11 | D16: MENGE | E16: Requisition quantity | F16: כמות | G16: -
A18: ◆ טבלה EBKN - חיוב דרישת רכש (לפק"ע) (Requisition account assignment)
A19: 12 | B19: ME51N; ME52N | C19: EBKN | D19: BANFN | E19: Purchase requisition number | F19: מספר דרישת רכש | G19: PK/FK | H19: • ACCOUNT_ASSIGNMENT_READ | I19: • קריאת נתוני חיוב לדרישה | J19: • RM06BANF | K19: • דוח דרישות רכש מחויבות לפק"ע | L19: מותאם (חיוב ל-ACDOCA) | M19: EBKN (זהה); עלות בפועל ב-ACDOCA | N19: ME51N; Fiori | O19: Manage Purchase Requisitions (אמת ID) | P19: עלויות מומרות ל-Universal Journal (ACDOCA) ב-SUM. COSP/COSS הופכים ל-Views. התאם דוחות עלות מותאמים והרצות התחשבנות.
A20: 13 | D20: BNFPO | E20: Requisition item | F20: פריט דרישה | G20: PK/FK
A21: 14 | D21: AUFNR | E21: Order (account assignment) | F21: פק"ע מחויבת | G21: FK
A22: 15 | D22: KOSTL | E22: Cost center | F22: מרכז עלות | G22: FK
A23: 16 | D23: SAKTO | E23: G/L account | F23: חשבון ראשי | G23: FK
A25: ◆ טבלה MSEG - פריטי מסמך חומר (תנועות מלאי) (Material document items)
A26: 17 | B26: MIGO/MB1A; MB31, MB1C | C26: MSEG | D26: MBLNR | E26: Material document number | F26: מספר מסמך חומר | G26: PK/FK | H26: • BAPI_GOODSMVT_CREATE • BAPI_GOODSMVT_GETITEMS | I26: • רישום תנועת מלאי • שליפת פריטי תנועה | J26: • RM07DOCS | K26: • דוח מסמכי חומר לפי פק"ע/תנועה | L26: הוחלף - מסמכי חומר מאוחדים ב-MATDOC | M26: MATDOC (MSEG=View תאימות) | N26: MIGO נתמך; Fiori | O26: Post Goods Movement (אמת ID) | P26: המרה אוטומטית ל-MATDOC ב-SUM (Silent Data Migration). MKPF/MSEG הופכים ל-Compatibility Views. בדוק קוד Z שקורא ישירות ל-MSEG/MKPF ועדכן ל-CDS/MATDOC.
A27: 18 | D27: ZEILE | E27: Material document item | F27: פריט מסמך | G27: PK
A28: 19 | D28: BWART | E28: Movement type (261/101) | F28: סוג תנועה | G28: -
A29: 20 | D29: MATNR | E29: Material | F29: חומר | G29: FK
A30: 21 | D30: MENGE | E30: Quantity | F30: כמות | G30: -
A31: 22 | D31: AUFNR | E31: Order (account assignment) | F31: פק"ע מחויבת | G31: FK
A33: ◆ טבלה MKPF - כותרת מסמך חומר (Material document header)
A34: 23 | B34: MIGO; MB1A | C34: MKPF | D34: MBLNR | E34: Material document number | F34: מספר מסמך חומר | G34: PK | H34: • BAPI_GOODSMVT_GETDETAIL | I34: • שליפת פרטי מסמך חומר | J34: • RM07DOCS | K34: • דוח מסמכי חומר | L34: הוחלף - מאוחד ב-MATDOC | M34: MATDOC (MKPF=View תאימות) | N34: MIGO נתמך; Fiori | O34: Post Goods Movement (אמת ID) | P34: המרה אוטומטית ל-MATDOC ב-SUM (Silent Data Migration). MKPF/MSEG הופכים ל-Compatibility Views. בדוק קוד Z שקורא ישירות ל-MSEG/MKPF ועדכן ל-CDS/MATDOC.
A35: 24 | D35: MJAHR | E35: Material document year | F35: שנת מסמך | G35: PK
A36: 25 | D36: BLDAT | E36: Document date | F36: תאריך מסמך | G36: -
A37: 26 | D37: BUDAT | E37: Posting date | F37: תאריך רישום | G37: -
A38: 27 | D38: USNAM | E38: User name | F38: משתמש | G38: -
A40: ◆ טבלה BUT000 - רשומת אב שותף עסקי (BP - השפעת מעבר על תפקידי PM) (Business Partner general data (S/4 transition impact on PM))
A41: 28 | B41: BP; (ECC: XK01/MK01 לספקים) | C41: BUT000 | D41: PARTNER | E41: Business partner number | F41: מספר שותף עסקי | G41: PK | H41: • BAPI_BUPA_CREATE_FROM_DATA • CVI_VENDOR_TO_BP_CONVERT | I41: • יצירת שותף עסקי • המרת ספק ל-BP (CVI) | J41: • MDS_LOAD_COCKPIT | K41: • סנכרון Customer/Vendor Integration ל-BP | L41: הוחלף - Business Partner מחליף ספקים/לקוחות (CVI חובה) | M41: BUT000 + LFA1 (View תאימות); ספק PM דרך BP | N41: BP (מחליף XK01/MK01) | O41: Manage Business Partner Master Data (אמת ID) | P41: נדרש CVI והמרת ספקים/לקוחות ל-Business Partner לפני/במהלך ההמרה (Pre-check חובה).
A42: 29 | D42: TYPE | E42: BP category (1=person/2=org/3=group) | F42: קטגוריית שותף | G42: -
A43: 30 | D43: BU_GROUP | E43: BP grouping (number range) | F43: קבוצת שותף | G43: -
A44: 31 | D44: BPKIND | E44: BP type | F44: סוג שותף | G44: -
A45: 32 | D45: NAME_ORG1 | E45: Organization name | F45: שם הארגון | G45: -
...

Sheet 10. עלויות והתחשבנות (PM-CO)
A1: ◄ חזרה למסך הראשי | C1: 10. עלויות והתחשבנות (PM-CO) | ECC 6.0 ➜ S/4HANA · CBC NEO
A2: מס' (#) | B2: טרנזקציות ECC (Main & Secondary) | C2: טבלת בסיס (Core Table) | D2: שדה טכני (Field) | E2: Field (English) | F2: שדה (עברית) | G2: סוג מפתח (Key Type) | H2: פונקציות / BAPIs | I2: תיאור הפונקציה | J2: תוכניות / דוחות | K2: תיאור התוכנית | L2: סטטוס S/4HANA | M2: טבלה/שדה חלופי ב-S/4 | N2: טרנז'/תוכנית מחליפה ב-S/4 | O2: אפליקציית Fiori (שם + ID) | P2: שלב מיגרציה / הערות SUM Conversion
A3: ◆ טבלה COSP - סך עלויות חיצוניות (Primary) (CO object cost totals - external postings)
A4: 1 | B4: KO88/KO8G; KOB1, S_ALR_87013611 | C4: COSP | D4: OBJNR | E4: CO object (order) | F4: אובייקט CO | G4: PK/FK | H4: • K_COSTS_READ • K_ORDER_SETTLEMENT | I4: • קריאת עלויות אובייקט • ביצוע התחשבנות פק"ע | J4: • RKO7KO88 | K4: • תוכנית ההתחשבנות (KO88) | L4: הוחלף - עלויות ב-Universal Journal | M4: ACDOCA (COSP=View תאימות) | N4: KO88 נתמך; Fiori Settlement | O4: Maintenance Order Actuals (אמת ID) | P4: עלויות מומרות ל-Universal Journal (ACDOCA) ב-SUM. COSP/COSS הופכים ל-Views. התאם דוחות עלות מותאמים והרצות התחשבנות.
A5: 2 | D5: KSTAR | E5: Cost element | F5: אלמנט עלות | G5: PK/FK
A6: 3 | D6: WRTTP | E6: Value type (01 plan/04 actual) | F6: סוג ערך | G6: PK
A7: 4 | D7: GJAHR | E7: Fiscal year | F7: שנת כספים | G7: PK
A8: 5 | D8: WTG001 | E8: Period value 001 | F8: ערך תקופה 001 | G8: -
A10: ◆ טבלה COSS - סך עלויות פנימיות (Secondary) (CO object cost totals - internal postings)
A11: 6 | B11: KO88; KOB1 | C11: COSS | D11: OBJNR | E11: CO object | F11: אובייקט CO | G11: PK/FK | H11: • K_COSTS_READ | I11: • קריאת עלויות פנימיות | J11: • RKAEP000 | K11: • דוח פריטי עלות בפועל | L11: הוחלף - עלויות ב-Universal Journal | M11: ACDOCA (COSS=View תאימות) | N11: KO88 נתמך; Fiori | O11: Maintenance Order Actuals (אמת ID) | P11: עלויות מומרות ל-Universal Journal (ACDOCA) ב-SUM. COSP/COSS הופכים ל-Views. התאם דוחות עלות מותאמים והרצות התחשבנות.
A12: 7 | D12: KSTAR | E12: Secondary cost element | F12: אלמנט עלות משני | G12: PK/FK
A13: 8 | D13: WRTTP | E13: Value type | F13: סוג ערך | G13: PK
A14: 9 | D14: GJAHR | E14: Fiscal year | F14: שנת כספים | G14: PK
A15: 10 | D15: PARGB | E15: Partner / sender object | F15: אובייקט שותף | G15: FK
A17: ◆ טבלה COBRA - כותרת חוק התחשבנות (Settlement rule header)
A18: 11 | B18: KO02; IW32 | C18: COBRA | D18: OBJNR | E18: Source object (order) | F18: אובייקט מקור | G18: PK/FK | H18: • K_SETTLEMENT_RULE_READ | I18: • קריאת חוק התחשבנות | J18: • RKACOR40 | K18: • איתור חוקי התחשבנות חסרים | L18: ללא שינוי (תואם) | M18: COBRA (זהה) | N18: KO02/IW32 (זהה) | O18: Manage Settlement Rules (אמת ID) | P18: ללא פעולת המרה ייעודית ב-SUM (טבלה תואמת). מומלץ Regression Test ואימות התאמות אישיות לאחר ההמרה.
A19: 12 | D19: BUREG | E19: Settlement rule | F19: חוק התחשבנות | G19: -
A20: 13 | D20: PERBZ | E20: Period type | F20: סוג תקופה | G20: -
A21: 14 | D21: ERLKZ | E21: Completion indicator | F21: מחוון השלמה | G21: -
A23: ◆ טבלה COBRB - פריטי חוק התחשבנות (חוקי חלוקה) (Settlement / distribution rules)
