Workbook

Sheet מסך ניווט מרכזי
N1: Type | O1: Code | P1: He | Q1: En | R1: Sheet | S1: Cell | T1: Link
B2: CBC ISRAEL | SAP PP-PI - מסך ניווט מרכזי | J2: ★ CBC Project NEO | N2: טרנזקציה | O2: MM01 | P2: Manage Product Master Data | Q2: F1602A | R2: 1. נתוני אב חומר ויחידות מידה ( | S2: A6 | T2: =HYPERLINK("#'"&R2&"'!"&S2,"➜ פתח")
B3: Project NEO - Production Planning for Process Industries | ECC 6.0 ➜ S/4HANA | N3: Fiori | O3: F1602A | P3: Manage Product Master Data | R3: 1. נתוני אב חומר ויחידות מידה ( | S3: A6 | T3: =HYPERLINK("#'"&R3&"'!"&S3,"➜ פתח")
N4: טרנזקציה | O4: MM50 | P4: Manage Product Master Data | Q4: F1602A | R4: 1. נתוני אב חומר ויחידות מידה ( | S4: A7 | T4: =HYPERLINK("#'"&R4&"'!"&S4,"➜ פתח")
B5: סיכום התקדמות מיגרציה (KPI - חי מה-Cockpit) | N5: Fiori | O5: F1602A | P5: Manage Product Master Data | R5: 1. נתוני אב חומר ויחידות מידה ( | S5: A7 | T5: =HYPERLINK("#'"&R5&"'!"&S5,"➜ פתח")
B6: =COUNTA('Cockpit מעקב מיגרציה'!$C$8:$C$72) | C6: =COUNTIF('Cockpit מעקב מיגרציה'!$D$8:$D$72,"Done") | D6: =COUNTIF('Cockpit מעקב מיגרציה'!$D$8:$D$72,"Tested") | E6: =(COUNTIF('Cockpit מעקב מיגרציה'!$D$8:$D$72,"In analysis")+COUNTIF('Cockpit מעקב מיגרציה'!$D$8:$D$72,"In conversion")) | F6: =COUNTIF('Cockpit מעקב מיגרציה'!$D$8:$D$72,"Not started") | G6: =IFERROR((COUNTIF('Cockpit מעקב מיגרציה'!$D$8:$D$72,"Done"))/(COUNTA('Cockpit מעקב מיגרציה'!$C$8:$C$72)),0) | N6: טרנזקציה | O6: MMSC | P6: Mass Maintenance - Products | Q6: - | R6: 1. נתוני אב חומר ויחידות מידה ( | S6: A8 | T6: =HYPERLINK("#'"&R6&"'!"&S6,"➜ פתח")
B7: סה"כ אובייקטים | C7: הושלם | D7: נבדק | E7: בתהליך | F7: פתוח | G7: % השלמה | N7: טרנזקציה | O7: CUNI | P7: Configure Units of Measure (SPRO) | Q7: - | R7: 1. נתוני אב חומר ויחידות מידה ( | S7: A9 | T7: =HYPERLINK("#'"&R7&"'!"&S7,"➜ פתח")
N8: BAPI | O8: BAPI_MATERIAL_SAVEDATA | P8: יצירה/עדכון אב חומר - ליבת הטעינה ההמונית והממשקים | R8: 1. נתוני אב חומר ויחידות מידה ( | S8: A12 | T8: =HYPERLINK("#'"&R8&"'!"&S8,"➜ פתח")
B9: ניווט מהיר לגיליונות | N9: BAPI | O9: BAPI_MATERIAL_GET_DETAIL | P9: שליפת נתוני חומר לדוחות/ממשקים | R9: 1. נתוני אב חומר ויחידות מידה ( | S9: A13 | T9: =HYPERLINK("#'"&R9&"'!"&S9,"➜ פתח")
B10: 1. נתוני אב חומר ויחידות מידה (Material & UoM) | D10: 2. עץ מוצר (BOM) | F10: 3. מתכון ייצור ופעולות (Master Recipe) | H10: 4. גרסאות ייצור (Production Versions - חובה ב-S/4) | N10: IDoc | O10: MATMAS (MATMAS05) | P10: הפצת אב חומר ל/מ-מערכות חיצוניות (Zetes/Daymax) | R10: 1. נתוני אב חומר ויחידות מידה ( | S10: A14 | T10: =HYPERLINK("#'"&R10&"'!"&S10,"➜ פתח")
N11: RFC | O11: MARA_SINGLE_READ / MARC_SINGLE_READ | P11: קריאת חומר/מפעל בודד | R11: 1. נתוני אב חומר ויחידות מידה ( | S11: A15 | T11: =HYPERLINK("#'"&R11&"'!"&S11,"➜ פתח")
N12: תוכנית | O12: RMMG2000 | P12: טעינה/עדכון חומר המוני (Direct Input) | R12: 1. נתוני אב חומר ויחידות מידה ( | S12: A18 | T12: =HYPERLINK("#'"&R12&"'!"&S12,"➜ פתח")
B13: 5. משאבים / מרכזי עבודה (Resources) | D13: 6. פק"ע ייצור ומתכון בקרה (Process Order) | F13: 7. קונפיגורציה (Customizing) | H13: ◆ Cockpit מעקב מיגרציה | N13: תוכנית | O13: RMDATIND | P13: Direct Input לאב חומר מממשק | R13: 1. נתוני אב חומר ויחידות מידה ( | S13: A19 | T13: =HYPERLINK("#'"&R13&"'!"&S13,"➜ פתח")
N14: תוכנית | O14: RMMM00B0 / MM60 | P14: דוח רשימת חומרים | R14: 1. נתוני אב חומר ויחידות מידה ( | S14: A20 | T14: =HYPERLINK("#'"&R14&"'!"&S14,"➜ פתח")
N15: טבלה | O15: MARA | P15: נתוני אב חומר כלליים | Q15: General material data | R15: 1. נתוני אב חומר ויחידות מידה ( | S15: A22 | T15: =HYPERLINK("#'"&R15&"'!"&S15,"➜ פתח")
B16: ⇄ ER - Join Map | N16: שדה | O16: MATNR | P16: מספר חומר | Q16: Material number | R16: 1. נתוני אב חומר ויחידות מידה ( | S16: C23 | T16: =HYPERLINK("#'"&R16&"'!"&S16,"➜ פתח")
N17: שדה | O17: MTART | P17: סוג חומר | Q17: Material type | R17: 1. נתוני אב חומר ויחידות מידה ( | S17: C24 | T17: =HYPERLINK("#'"&R17&"'!"&S17,"➜ פתח")
N18: שדה | O18: MEINS | P18: יחידת מידה בסיסית | Q18: Base unit of measure | R18: 1. נתוני אב חומר ויחידות מידה ( | S18: C25 | T18: =HYPERLINK("#'"&R18&"'!"&S18,"➜ פתח")
N19: שדה | O19: MATKL | P19: קבוצת חומר | Q19: Material group | R19: 1. נתוני אב חומר ויחידות מידה ( | S19: C26 | T19: =HYPERLINK("#'"&R19&"'!"&S19,"➜ פתח")
N20: שדה | O20: GROES | P20: גודל / מידות | Q20: Size / dimensions | R20: 1. נתוני אב חומר ויחידות מידה ( | S20: C27 | T20: =HYPERLINK("#'"&R20&"'!"&S20,"➜ פתח")
N21: שדה | O21: BRGEW | P21: משקל ברוטו | Q21: Gross weight | R21: 1. נתוני אב חומר ויחידות מידה ( | S21: C28 | T21: =HYPERLINK("#'"&R21&"'!"&S21,"➜ פתח")
N22: שדה | O22: NTGEW | P22: משקל נטו | Q22: Net weight | R22: 1. נתוני אב חומר ויחידות מידה ( | S22: C29 | T22: =HYPERLINK("#'"&R22&"'!"&S22,"➜ פתח")
N23: שדה | O23: XCHPF | P23: ניהול אצוות | Q23: Batch management indicator | R23: 1. נתוני אב חומר ויחידות מידה ( | S23: C30 | T23: =HYPERLINK("#'"&R23&"'!"&S23,"➜ פתח")
B24: 🔍 חיפוש גלובלי (טבלה / שדה / טרנזקציה - עברית/אנגלית) | N24: טרנזקציה | O24: MM01 | P24: נתוני אב חומר כלליים | Q24: General material data | R24: 1. נתוני אב חומר ויחידות מידה ( | S24: A23 | T24: =HYPERLINK("#'"&R24&"'!"&S24,"➜ פתח")
B25: הקלד כאן: | N25: טרנזקציה | O25: MM02 | P25: נתוני אב חומר כלליים | Q25: General material data | R25: 1. נתוני אב חומר ויחידות מידה ( | S25: A23 | T25: =HYPERLINK("#'"&R25&"'!"&S25,"➜ פתח")
N26: טרנזקציה | O26: MM03 | P26: נתוני אב חומר כלליים | Q26: General material data | R26: 1. נתוני אב חומר ויחידות מידה ( | S26: A23 | T26: =HYPERLINK("#'"&R26&"'!"&S26,"➜ פתח")
B27: קישור | C27: קוד | D27: עברית | E27: English | F27: גיליון | G27: תא | N27: טרנזקציה | O27: MM50 | P27: נתוני אב חומר כלליים | Q27: General material data | R27: 1. נתוני אב חומר ויחידות מידה ( | S27: A23 | T27: =HYPERLINK("#'"&R27&"'!"&S27,"➜ פתח")
B28: =IF(C25="","הקלד מונח וקבל תוצאות מיידיות...",IFERROR(_xlfn._xlws.FILTER(CHOOSE({1,2,3,4,5,6},$T$2:$T$649,$O$2:$O$649,$P$2:$P$649,$Q$2:$Q$649,$R$2:$R$649,$S$2:$S$649),(ISNUMBER(SEARCH(C25,$O$2:$O$649)))+(ISNUMBER(SEARCH(C25,$P$2:$P$649)))+(ISNUMBER(SEARCH(C25,$Q$2:$Q$649)))+(ISNUMBER(SEARCH(C25,$N$2:$N$649)))>0),"לא נמצאו תוצאות")) | N28: טרנזקציה | O28: MMSC | P28: נתוני אב חומר כלליים | Q28: General material data | R28: 1. נתוני אב חומר ויחידות מידה ( | S28: A23 | T28: =HYPERLINK("#'"&R28&"'!"&S28,"➜ פתח")
N29: טבלה | O29: MAKT | P29: תיאורי חומר (טקסטים) | Q29: Material descriptions | R29: 1. נתוני אב חומר ויחידות מידה ( | S29: A32 | T29: =HYPERLINK("#'"&R29&"'!"&S29,"➜ פתח")
N30: שדה | O30: MATNR | P30: מספר חומר | Q30: Material number | R30: 1. נתוני אב חומר ויחידות מידה ( | S30: C33 | T30: =HYPERLINK("#'"&R30&"'!"&S30,"➜ פתח")
N31: שדה | O31: SPRAS | P31: שפה | Q31: Language key | R31: 1. נתוני אב חומר ויחידות מידה ( | S31: C34 | T31: =HYPERLINK("#'"&R31&"'!"&S31,"➜ פתח")
N32: שדה | O32: MAKTX | P32: תיאור חומר | Q32: Material description | R32: 1. נתוני אב חומר ויחידות מידה ( | S32: C35 | T32: =HYPERLINK("#'"&R32&"'!"&S32,"➜ פתח")
N33: שדה | O33: MAKTG | P33: תיאור (אותיות גדולות) | Q33: Description (upper case) | R33: 1. נתוני אב חומר ויחידות מידה ( | S33: C36 | T33: =HYPERLINK("#'"&R33&"'!"&S33,"➜ פתח")
N34: טרנזקציה | O34: MM01 | P34: תיאורי חומר (טקסטים) | Q34: Material descriptions | R34: 1. נתוני אב חומר ויחידות מידה ( | S34: A33 | T34: =HYPERLINK("#'"&R34&"'!"&S34,"➜ פתח")
N35: טרנזקציה | O35: MM02 | P35: תיאורי חומר (טקסטים) | Q35: Material descriptions | R35: 1. נתוני אב חומר ויחידות מידה ( | S35: A33 | T35: =HYPERLINK("#'"&R35&"'!"&S35,"➜ פתח")
N36: טרנזקציה | O36: MM03 | P36: תיאורי חומר (טקסטים) | Q36: Material descriptions | R36: 1. נתוני אב חומר ויחידות מידה ( | S36: A33 | T36: =HYPERLINK("#'"&R36&"'!"&S36,"➜ פתח")
N37: טבלה | O37: MARC | P37: נתוני חומר ברמת מפעל | Q37: Plant data for material | R37: 1. נתוני אב חומר ויחידות מידה ( | S37: A38 | T37: =HYPERLINK("#'"&R37&"'!"&S37,"➜ פתח")
N38: שדה | O38: MATNR | P38: מספר חומר | Q38: Material number | R38: 1. נתוני אב חומר ויחידות מידה ( | S38: C39 | T38: =HYPERLINK("#'"&R38&"'!"&S38,"➜ פתח")
N39: שדה | O39: WERKS | P39: מפעל | Q39: Plant | R39: 1. נתוני אב חומר ויחידות מידה ( | S39: C40 | T39: =HYPERLINK("#'"&R39&"'!"&S39,"➜ פתח")
N40: שדה | O40: DISPO | P40: אחראי MRP | Q40: MRP controller | R40: 1. נתוני אב חומר ויחידות מידה ( | S40: C41 | T40: =HYPERLINK("#'"&R40&"'!"&S40,"➜ פתח")
...

Sheet 1. נתוני אב חומר ויחידות מידה (
A1: ◄ חזרה למסך הראשי | C1: 1. נתוני אב חומר ויחידות מידה (Material & UoM) | ECC 6.0 ➜ S/4HANA · CBC NEO
A2: מס' (#) | B2: טבלה (Table) | C2: שדה טכני (Field) | D2: סוג נתונים (Type) | E2: אורך (Len) | F2: מפתח (Key) | G2: English Term | H2: תרגום עברי (Hebrew) | I2: JOIN ON (SQL / CDS) | J2: הסבר פונקציונלי בעברית | K2: פער / הערת S/4HANA | L2: SAP Help
A3: 🔧 שכבה תפעולית (Operational Layer) - T-codes ◄► Fiori | ממשקים BAPI/IDoc/RFC | תוכניות רקע ודוחות
A4: מיפוי T-code ◄► Fiori App (ECC ◄► S/4HANA)
A5: ECC T-code | D5: S/4HANA Fiori App | I5: Fiori ID
A6: MM01 / MM02 / MM03 | D6: Manage Product Master Data | I6: F1602A
A7: MM50 (extend views) | D7: Manage Product Master Data | I7: F1602A
A8: MMSC (ext. storage loc.) | D8: Mass Maintenance - Products | I8: -
A9: CUNI (UoM config) | D9: Configure Units of Measure (SPRO) | I9: -
A10: ממשקים ובלוקים פונקציונליים: BAPIs / IDocs / RFCs (Extraction & Messaging)
A11: Type | C11: Name | G11: תיאור / Description
A12: BAPI | C12: BAPI_MATERIAL_SAVEDATA | G12: יצירה/עדכון אב חומר - ליבת הטעינה ההמונית והממשקים
A13: BAPI | C13: BAPI_MATERIAL_GET_DETAIL | G13: שליפת נתוני חומר לדוחות/ממשקים
A14: IDoc | C14: MATMAS (MATMAS05) | G14: הפצת אב חומר ל/מ-מערכות חיצוניות (Zetes/Daymax)
A15: RFC | C15: MARA_SINGLE_READ / MARC_SINGLE_READ | G15: קריאת חומר/מפעל בודד
A16: תוכניות רקע ודוחות סטנדרטיים (Background Programs / Reports)
A17: Program / Report | E17: תיאור ומטרה / Usage & Trigger
A18: RMMG2000 | E18: טעינה/עדכון חומר המוני (Direct Input)
A19: RMDATIND | E19: Direct Input לאב חומר מממשק
A20: RMMM00B0 / MM60 | E20: דוח רשימת חומרים
A22: ◆ טבלה MARA - נתוני אב חומר כלליים (General material data) | T-codes: MM01/MM02/MM03; MM50, MMSC
A23: 1 | B23: MARA | C23: MATNR | D23: CHAR | E23: 18->40 | F23: PK | G23: Material number | H23: מספר חומר | I23: (header - root of material model) | J23: טבלת הליבה של כל חומר ב-CBC (חומרי גלם, תרכיזים, חומרי אריזה, מוצרים מוגמרים). מפתח MATNR מורחב מ-18 ל-40 תווים ב-S/4HANA - קריטי לממשקי IDoc ל-Zetes/Daymax ולברקודים. כל פעולת ייצור (COR1/COR2) נשענת על רשומת חומר תקינה. | K23: MATNR מורחב 18->40 (SAP Note 2267140); בדוק ממשקים, ברקודים והמרות EAN. | L23: SAP Help - Material Master
A24: 2 | C24: MTART | D24: CHAR | E24: 4 | F24: FK | G24: Material type | H24: סוג חומר
A25: 3 | C25: MEINS | D25: UNIT | E25: 3 | F25: FK | G25: Base unit of measure | H25: יחידת מידה בסיסית
A26: 4 | C26: MATKL | D26: CHAR | E26: 9 | F26: FK | G26: Material group | H26: קבוצת חומר
A27: 5 | C27: GROES | D27: CHAR | E27: 32 | F27: - | G27: Size / dimensions | H27: גודל / מידות
A28: 6 | C28: BRGEW | D28: QUAN | E28: 13 | F28: - | G28: Gross weight | H28: משקל ברוטו
A29: 7 | C29: NTGEW | D29: QUAN | E29: 13 | F29: - | G29: Net weight | H29: משקל נטו
A30: 8 | C30: XCHPF | D30: CHAR | E30: 1 | F30: - | G30: Batch management indicator | H30: ניהול אצוות
A32: ◆ טבלה MAKT - תיאורי חומר (טקסטים) (Material descriptions) | T-codes: MM01/MM02/MM03
A33: 9 | B33: MAKT | C33: MATNR | D33: CHAR | E33: 18->40 | F33: PK/FK | G33: Material number | H33: מספר חומר | I33: FROM MAKT JOIN MARA ON MAKT.MATNR = MARA.MATNR | J33: תיאורי החומר הרב-לשוניים (עברית/אנגלית) המוצגים בפק"ע, בתעודות ובממשקי הלוגיסטיקה. חיוני לתצוגה דו-לשונית במסופי Zetes. | K33: ללא שינוי; MATNR מורחב משפיע על המפתח. | L33: SAP Help - Material Master
A34: 10 | C34: SPRAS | D34: LANG | E34: 1 | F34: PK | G34: Language key | H34: שפה
A35: 11 | C35: MAKTX | D35: CHAR | E35: 40 | F35: - | G35: Material description | H35: תיאור חומר
A36: 12 | C36: MAKTG | D36: CHAR | E36: 40 | F36: - | G36: Description (upper case) | H36: תיאור (אותיות גדולות)
A38: ◆ טבלה MARC - נתוני חומר ברמת מפעל (Plant data for material) | T-codes: MM01/MM02; MD04, CO09
A39: 13 | B39: MARC | C39: MATNR | D39: CHAR | E39: 18->40 | F39: PK/FK | G39: Material number | H39: מספר חומר | I39: FROM MARC JOIN MARA ON MARC.MATNR = MARA.MATNR | J39: פרמטרי התכנון והייצור של החומר במפעל CBC הספציפי: סוג רכש, MRP, אופק תכנון, גרסת ייצור ברירת מחדל. שדה SBDKZ/SFCPF שולט בזרימת הייצור (Process Order). | K39: MRP Live מחליף MRP קלאסי; שדות תכנון נשמרים אך הביצוע ב-MATDOC/ACDOCA. | L39: SAP Help - Plant Data
A40: 14 | C40: WERKS | D40: CHAR | E40: 4 | F40: PK | G40: Plant | H40: מפעל
A41: 15 | C41: DISPO | D41: CHAR | E41: 3 | F41: FK | G41: MRP controller | H41: אחראי MRP
A42: 16 | C42: DISMM | D42: CHAR | E42: 2 | F42: - | G42: MRP type | H42: סוג MRP
A43: 17 | C43: BESKZ | D43: CHAR | E43: 1 | F43: - | G43: Procurement type | H43: סוג רכש
...

Sheet 2. עץ מוצר (BOM)
A1: ◄ חזרה למסך הראשי | C1: 2. עץ מוצר (BOM) | ECC 6.0 ➜ S/4HANA · CBC NEO
A2: מס' (#) | B2: טבלה (Table) | C2: שדה טכני (Field) | D2: סוג נתונים (Type) | E2: אורך (Len) | F2: מפתח (Key) | G2: English Term | H2: תרגום עברי (Hebrew) | I2: JOIN ON (SQL / CDS) | J2: הסבר פונקציונלי בעברית | K2: פער / הערת S/4HANA | L2: SAP Help
A3: 🔧 שכבה תפעולית (Operational Layer) - T-codes ◄► Fiori | ממשקים BAPI/IDoc/RFC | תוכניות רקע ודוחות
A4: מיפוי T-code ◄► Fiori App (ECC ◄► S/4HANA)
A5: ECC T-code | D5: S/4HANA Fiori App | I5: Fiori ID
A6: CS01 / CS02 / CS03 | D6: Maintain Bill of Material | I6: F1743
A7: CS11 / CS12 / CS15 | D7: Manage Material BOMs | I7: F1813
A8: CEWB (eng. workbench) | D8: Manage Bill of Materials | I8: F1813
A9: ממשקים ובלוקים פונקציונליים: BAPIs / IDocs / RFCs (Extraction & Messaging)
A10: Type | C10: Name | G10: תיאור / Description
A11: BAPI | C11: BAPI_MATERIAL_BOM_GROUP_CREATE | G11: יצירת עץ מוצר (S/4 BOM API)
A12: FM | C12: CSAP_MAT_BOM_MAINTAIN | G12: תחזוקת עץ מוצר (ECC)
A13: IDoc | C13: BOMMAT | G13: הפצת עץ מוצר חומר בין מערכות
A14: RFC | C14: CS_BOM_EXPL_MAT_RC1 | G14: פיצוץ עץ מוצר לחומר
A15: תוכניות רקע ודוחות סטנדרטיים (Background Programs / Reports)
A16: Program / Report | E16: תיאור ומטרה / Usage & Trigger
A17: RCSBOM00 | E17: עיבוד/בדיקת עצי מוצר המוני
A18: RCSBI010 | E18: פיצוץ עץ מוצר רב-רמתי
A19: CS_BT | E19: דוח Where-Used לרכיב
A21: ◆ טבלה MAST - קישור חומר לעץ מוצר (Material to BOM link) | T-codes: CS01/CS02/CS03
A22: 1 | B22: MAST | C22: MATNR | D22: CHAR | E22: 18->40 | F22: PK/FK | G22: Material number | H22: מספר חומר | I22: FROM MAST JOIN MARA ON MAST.MATNR = MARA.MATNR | J22: מקשר בין חומר/מפעל לבין עץ המוצר (Recipe BOM). מפתח ההצטרפות לכל פיצוץ רכיבים בפק"ע. עץ מוצר = 'עץ מוצר' / Bill of Material. | K22: ללא שינוי; MATNR מורחב משפיע על המפתח ועל IDNRK. | L22: SAP Help - Bill of Material
A23: 2 | C23: WERKS | D23: CHAR | E23: 4 | F23: PK | G23: Plant | H23: מפעל
A24: 3 | C24: STLAN | D24: CHAR | E24: 1 | F24: PK | G24: BOM usage (1=Production) | H24: שימוש עץ מוצר
A25: 4 | C25: STLNR | D25: CHAR | E25: 8 | F25: FK | G25: Bill of material number | H25: מספר עץ מוצר
A26: 5 | C26: STLAL | D26: CHAR | E26: 2 | F26: PK | G26: Alternative BOM | H26: חלופת עץ מוצר
A28: ◆ טבלה STKO - כותרת עץ מוצר (BOM header) | T-codes: CS01/CS02/CS03
A29: 6 | B29: STKO | C29: STLTY | D29: CHAR | E29: 1 | F29: PK | G29: BOM category | H29: קטגוריית עץ מוצר | I29: FROM STKO JOIN MAST ON STKO.STLNR = MAST.STLNR | J29: כותרת עץ המוצר: כמות בסיס, יחידה, סטטוס ותוקף. כמות הבסיס (BMENG) קובעת את יחס הרכיבים - קריטי לדיוק מתכון/פחת. | K29: ללא שינוי. | L29: SAP Help - BOM Header
A30: 7 | C30: STLNR | D30: CHAR | E30: 8 | F30: PK | G30: Bill of material number | H30: מספר עץ מוצר
A31: 8 | C31: STLAL | D31: CHAR | E31: 2 | F31: PK | G31: Alternative BOM | H31: חלופת עץ מוצר
A32: 9 | C32: BMENG | D32: QUAN | E32: 13 | F32: - | G32: Base quantity | H32: כמות בסיס
A33: 10 | C33: BMEIN | D33: UNIT | E33: 3 | F33: FK | G33: Base unit of measure | H33: יחידת בסיס
A34: 11 | C34: STLST | D34: NUMC | E34: 2 | F34: - | G34: BOM status | H34: סטטוס עץ מוצר
A36: ◆ טבלה STPO - פריטי עץ מוצר (רכיבים) (BOM item) | T-codes: CS02; CS11, CS15
A37: 12 | B37: STPO | C37: STLTY | D37: CHAR | E37: 1 | F37: PK/FK | G37: BOM category | H37: קטגוריית עץ מוצר | I37: FROM STPO JOIN STKO ON STPO.STLNR = STKO.STLNR AND STPO.STLTY = STKO.STLTY | J37: רכיבי עץ המוצר: כל חומר גלם/אריזה, כמותו (MENGE) וסוג הפריט. כאן מוגדר פחת רכיב (AUSCH %) לבקרת 1% פחת ייצור. | K37: ללא שינוי; IDNRK מורחב 18->40. | L37: SAP Help - BOM Item
A38: 13 | C38: STLNR | D38: CHAR | E38: 8 | F38: PK/FK | G38: Bill of material number | H38: מספר עץ מוצר
A39: 14 | C39: STLKN | D39: NUMC | E39: 8 | F39: PK | G39: BOM item node number | H39: מספר צומת פריט
A40: 15 | C40: POSNR | D40: CHAR | E40: 4 | F40: - | G40: BOM item number | H40: מספר פריט
A41: 16 | C41: IDNRK | D41: CHAR | E41: 18->40 | F41: FK | G41: Component (BOM item material) | H41: רכיב / חומר
A42: 17 | C42: MENGE | D42: QUAN | E42: 13 | F42: - | G42: Component quantity | H42: כמות רכיב
A43: 18 | C43: MEINS | D43: UNIT | E43: 3 | F43: FK | G43: Component unit | H43: יחידת רכיב
...

Sheet 3. מתכון ייצור ופעולות (Master 
A1: ◄ חזרה למסך הראשי | C1: 3. מתכון ייצור ופעולות (Master Recipe) | ECC 6.0 ➜ S/4HANA · CBC NEO
A2: מס' (#) | B2: טבלה (Table) | C2: שדה טכני (Field) | D2: סוג נתונים (Type) | E2: אורך (Len) | F2: מפתח (Key) | G2: English Term | H2: תרגום עברי (Hebrew) | I2: JOIN ON (SQL / CDS) | J2: הסבר פונקציונלי בעברית | K2: פער / הערת S/4HANA | L2: SAP Help
A3: 🔧 שכבה תפעולית (Operational Layer) - T-codes ◄► Fiori | ממשקים BAPI/IDoc/RFC | תוכניות רקע ודוחות
A4: מיפוי T-code ◄► Fiori App (ECC ◄► S/4HANA)
A5: ECC T-code | D5: S/4HANA Fiori App | I5: Fiori ID
A6: C201 / C202 / C203 | D6: Manage Master Recipes | I6: -
A7: C251 (print) | D7: Master Recipe Print | I7: -
A8: COIO (production cockpit) | D8: Process Order Information System | I8: -
A9: ממשקים ובלוקים פונקציונליים: BAPIs / IDocs / RFCs (Extraction & Messaging)
A10: Type | C10: Name | G10: תיאור / Description
A11: RFC | C11: CP_RECIPE_READ | G11: קריאת מתכון ייצור
A12: BAPI | C12: BAPI_CENTRAL_CHARACT_CREATE | G12: יצירת מאפיין בדיקה ראשי (QM)
A13: IDoc | C13: LOIPRO | G13: הוראות ייצור - מהמתכון לפק"ע ולקו
A14: PI | C14: Control Recipe / PI Sheet (PI Messages) | G14: שליחת הוראות תהליך לבקר/MES (Zetes/Daymax)
A15: תוכניות רקע ודוחות סטנדרטיים (Background Programs / Reports)
A16: Program / Report | E16: תיאור ומטרה / Usage & Trigger
A17: RCEXMASS | E17: עיבוד המוני מתכונים
A18: RCPRECIPE | E18: דוח/הערכת מתכונים
A19: RCO_CONTROL_RECIPE | E19: יצירת/שליחת Control Recipe
A21: ◆ טבלה PLKO - כותרת מתכון ייצור / רשימת פעולות (Task list / recipe header) | T-codes: C201/C202/C203
A22: 1 | B22: PLKO | C22: PLNTY | D22: CHAR | E22: 1 | F22: PK | G22: Task list type (2=recipe) | H22: סוג רשימה | I22: FROM PLKO JOIN MAPL ON PLKO.PLNTY = MAPL.PLNTY AND PLKO.PLNNR = MAPL.PLNNR | J22: כותרת מתכון הייצור (Master Recipe, PLNTY='2'). מגדיר אצווה תקנית, סטטוס ושימוש. 'מתכון ייצור' = Master Recipe. ב-CBC כל משקה מיוצר לפי מתכון מאושר. | K22: ללא שינוי מבני; Fiori 'Manage Master Recipes'. | L22: SAP Help - Master Recipe
A23: 2 | C23: PLNNR | D23: CHAR | E23: 8 | F23: PK | G23: Key for task list group | H23: קבוצת רשימת פעולות
A24: 3 | C24: PLNAL | D24: CHAR | E24: 2 | F24: PK | G24: Group counter | H24: מונה קבוצה / חלופה
A25: 4 | C25: VERWE | D25: CHAR | E25: 3 | F25: FK | G25: Task list usage | H25: שימוש
A26: 5 | C26: STATU | D26: CHAR | E26: 2 | F26: - | G26: Task list status | H26: סטטוס
A27: 6 | C27: LOSVN | D27: QUAN | E27: 13 | F27: - | G27: Lot size from | H27: גודל אצווה מ
A28: 7 | C28: LOSBS | D28: QUAN | E28: 13 | F28: - | G28: Lot size to | H28: גודל אצווה עד
A30: ◆ טבלה PLPO - פעולות/פאזות במתכון (Task list - operation / activity) | T-codes: C202
A31: 8 | B31: PLPO | C31: PLNTY | D31: CHAR | E31: 1 | F31: PK/FK | G31: Task list type | H31: סוג רשימה | I31: FROM PLPO JOIN PLAS ON PLPO.PLNTY = PLAS.PLNTY AND PLPO.PLNNR = PLAS.PLNNR AND PLPO.PLNKN = PLAS.PLNKN | J31: פעולות ופאזות הייצור (ערבוב, פסטור, מילוי). מפתח בקרה (STEUS) קובע אם הפעולה פנימית/קבלן, ומפעיל הוראות תהליך (Process Instructions) ל-PI sheet ולבקרים. ARBPL=משאב. | K31: ללא שינוי; ביצוע דרך Control Recipe / PI sheet. | L31: SAP Help - Recipe Operations
A32: 9 | C32: PLNNR | D32: CHAR | E32: 8 | F32: PK/FK | G32: Task list group | H32: קבוצת רשימה
A33: 10 | C33: PLNKN | D33: NUMC | E33: 8 | F33: PK | G33: Node number (operation) | H33: מספר צומת פעולה
A34: 11 | C34: VORNR | D34: CHAR | E34: 4 | F34: - | G34: Operation number | H34: מספר פעולה
A35: 12 | C35: ARBID | D35: NUMC | E35: 8 | F35: FK | G35: Work center / resource (object id) | H35: משאב (מזהה אובייקט)
A36: 13 | C36: STEUS | D36: CHAR | E36: 4 | F36: FK | G36: Control key | H36: מפתח בקרה
A37: 14 | C37: LTXA1 | D37: CHAR | E37: 40 | F37: - | G37: Operation short text | H37: תיאור פעולה
A38: 15 | C38: VGW01 | D38: QUAN | E38: 9 | F38: - | G38: Standard value 1 (setup) | H38: ערך תקן 1 (הקמה)
A39: 16 | C39: VGW02 | D39: QUAN | E39: 9 | F39: - | G39: Standard value 2 (machine) | H39: ערך תקן 2 (מכונה)
A41: ◆ טבלה PLAS - שיוך/בחירת פעולות לרשימה (Task list - operation selection) | T-codes: C202
A42: 17 | B42: PLAS | C42: PLNTY | D42: CHAR | E42: 1 | F42: PK/FK | G42: Task list type | H42: סוג רשימה | I42: FROM PLAS JOIN PLKO ON PLAS.PLNTY = PLKO.PLNTY AND PLAS.PLNNR = PLKO.PLNNR | J42: מקשר פעולות (PLPO) לכותרת ולרצף, ושולט בתוקף לפי שינוי הנדסי. שכבת הבחירה של הפעולות התקפות. | K42: ללא שינוי. | L42: SAP Help - Operation Selection
A43: 18 | C43: PLNNR | D43: CHAR | E43: 8 | F43: PK/FK | G43: Task list group | H43: קבוצת רשימה
...

Sheet 4. גרסאות ייצור (Production Ver
A1: ◄ חזרה למסך הראשי | C1: 4. גרסאות ייצור (Production Versions - חובה ב-S/4) | ECC 6.0 ➜ S/4HANA · CBC NEO
A2: מס' (#) | B2: טבלה (Table) | C2: שדה טכני (Field) | D2: סוג נתונים (Type) | E2: אורך (Len) | F2: מפתח (Key) | G2: English Term | H2: תרגום עברי (Hebrew) | I2: JOIN ON (SQL / CDS) | J2: הסבר פונקציונלי בעברית | K2: פער / הערת S/4HANA | L2: SAP Help
A3: 🔧 שכבה תפעולית (Operational Layer) - T-codes ◄► Fiori | ממשקים BAPI/IDoc/RFC | תוכניות רקע ודוחות
A4: מיפוי T-code ◄► Fiori App (ECC ◄► S/4HANA)
A5: ECC T-code | D5: S/4HANA Fiori App | I5: Fiori ID
A6: C223 | D6: Manage Production Versions | I6: F2703
A7: MM02 (PV tab) | D7: Manage Product Master Data | I7: F1602A
A8: CC01/CC02 (ECM) | D8: Manage Change Records | I8: -
A9: ממשקים ובלוקים פונקציונליים: BAPIs / IDocs / RFCs (Extraction & Messaging)
A10: Type | C10: Name | G10: תיאור / Description
A11: BAPI | C11: BAPI_MATERIAL_SAVEDATA (PVERSIONS) | G11: יצירה/עדכון גרסת ייצור
A12: BAPI | C12: BAPI_PRODVERS_CREATE_REPLACE | G12: יצירה/החלפת גרסת ייצור (אמת)
A13: FM | C13: CM_FV_PROD_VERS_READ | G13: קריאת גרסאות ייצור לחומר/מפעל
A14: תוכניות רקע ודוחות סטנדרטיים (Background Programs / Reports)
A15: Program / Report | E15: תיאור ומטרה / Usage & Trigger
A16: RCC22300 / RSC22300 | E16: בדיקת עקביות המונית של גרסאות ייצור (Pre-check ל-S/4)
A17: CS_BD_DIRECT_LINK | E17: יצירת קישור ישיר BOM<->Recipe לגרסה
A19: ◆ טבלה MKAL - גרסאות ייצור לחומר (Production versions for materials) | T-codes: C223; MM02 (PV)
A20: 1 | B20: MKAL | C20: MATNR | D20: CHAR | E20: 18->40 | F20: PK/FK | G20: Material number | H20: מספר חומר | I20: FROM MKAL JOIN MARC ON MKAL.MATNR = MARC.MATNR AND MKAL.WERKS = MARC.WERKS | J20: 'גרסת ייצור' (Production Version) מקשרת חומר -> עץ מוצר (STLAL) + מתכון (PLNNR) + קו ייצור. ב-S/4HANA היא חובה מוחלטת (100%) לכל ביצוע ייצור - מחליפה את לוגיקת בחירת BOM/Routing האוטומטית של ECC. ב-CBC כל שילוב מוצר/קו = גרסה. ללא PV תקפה הפק"ע (COR1) לא תיווצר. | K20: חובה 100% ב-S/4HANA - הרץ C223 ובדוק תוקף/עקביות לכל חומר מיוצר לפני ההמרה (Pre-check קריטי). | L20: SAP Note - Production Versions Mandatory
A21: 2 | C21: WERKS | D21: CHAR | E21: 4 | F21: PK/FK | G21: Plant | H21: מפעל
A22: 3 | C22: VERID | D22: CHAR | E22: 4 | F22: PK | G22: Production version | H22: מזהה גרסת ייצור
A23: 4 | C23: TEXT1 | D23: CHAR | E23: 40 | F23: - | G23: Production version text | H23: תיאור גרסת ייצור
A24: 5 | C24: ADATU | D24: DATS | E24: 8 | F24: - | G24: Valid-from date | H24: תקף מ
A25: 6 | C25: BDATU | D25: DATS | E25: 8 | F25: - | G25: Valid-to date | H25: תקף עד
A26: 7 | C26: BSTMI | D26: QUAN | E26: 13 | F26: - | G26: Lot size from | H26: גודל אצווה מ
A27: 8 | C27: BSTMA | D27: QUAN | E27: 13 | F27: - | G27: Lot size to | H27: גודל אצווה עד
A28: 9 | C28: STLAL | D28: CHAR | E28: 2 | F28: FK | G28: Alternative BOM | H28: חלופת עץ מוצר
A29: 10 | C29: STLAN | D29: CHAR | E29: 1 | F29: FK | G29: BOM usage | H29: שימוש עץ מוצר
A30: 11 | C30: PLNTY | D30: CHAR | E30: 1 | F30: FK | G30: Task list type (recipe) | H30: סוג רשימה
A31: 12 | C31: PLNNR | D31: CHAR | E31: 8 | F31: FK | G31: Task list group (recipe) | H31: קבוצת מתכון
A32: 13 | C32: ALNAL | D32: CHAR | E32: 2 | F32: FK | G32: Task list group counter | H32: מונה רשימה
... A34: 15 | C34: PRFG_NEW | D34: CHAR | E34: 1 | F34: - | G34: Detailed PV check status | H34: סטטוס בדיקת תקינות

Sheet 5. משאבים  מרכזי עבודה (Resourc
A1: ◄ חזרה למסך הראשי | C1: 5. משאבים / מרכזי עבודה (Resources) | ECC 6.0 ➜ S/4HANA · CBC NEO
A2: מס' (#) | B2: טבלה (Table) | C2: שדה טכני (Field) | D2: סוג נתונים (Type) | E2: אורך (Len) | F2: מפתח (Key) | G2: English Term | H2: תרגום עברי (Hebrew) | I2: JOIN ON (SQL / CDS) | J2: הסבר פונקציונלי בעברית | K2: פער / הערת S/4HANA | L2: SAP Help
A3: 🔧 שכבה תפעולית (Operational Layer) - T-codes ◄► Fiori | ממשקים BAPI/IDoc/RFC | תוכניות רקע ודוחות
A4: מיפוי T-code ◄► Fiori App (ECC ◄► S/4HANA)
A5: ECC T-code | D5: S/4HANA Fiori App | I5: Fiori ID
A6: CRC1 / CRC2 / CRC3 | D6: Manage Work Centers / Resources | I6: F3794
A7: CR11 / CR12 / CR13 | D7: Manage Capacity | I7: -
A8: KP26 (activity rates) | D8: Manage Cost Rates | I8: -
A9: ממשקים ובלוקים פונקציונליים: BAPIs / IDocs / RFCs (Extraction & Messaging)
A10: Type | C10: Name | G10: תיאור / Description
A11: RFC | C11: CR_WORK_CENTER_READ | G11: קריאת נתוני מרכז עבודה/משאב
A12: FM | C12: CRAP_WORKCENTER_GET_DETAIL | G12: שליפת פרטי משאב
A13: FM | C13: CY_CAPACITY_LOAD | G13: חישוב עומס קיבולת
A14: תוכניות רקע ודוחות סטנדרטיים (Background Programs / Reports)
A15: Program / Report | E15: תיאור ומטרה / Usage & Trigger
A16: RCCRSE00 / CR05 | E16: דוח מרכזי עבודה/משאבים
A17: RIABC000 | E17: ניתוח קיבולת / ABC (אמת)
A18: RCCYPL00 / CM01 | E18: הערכת עומסי קיבולת
A20: ◆ טבלה CRHD - כותרת משאב / מרכז עבודה (Work center / resource header) | T-codes: CRC1/CRC2/CRC3; CR01
A21: 1 | B21: CRHD | C21: OBJTY | D21: CHAR | E21: 2 | F21: PK | G21: Object type (A=work center) | H21: סוג אובייקט | I21: (header - root of resource model) | J21: המשאב (קו מילוי, ערבל, פסטרייזר) שעליו מתבצעות פעולות המתכון. OBJTY='A'. מקושר לקיבולת ולמרכז עלות. ב-CBC כל קו ייצור = משאב עם קיבולת מתוזמנת. | K21: ללא שינוי מבני; Fiori 'Manage Work Centers'. | L21: SAP Help - Work Center
A22: 2 | C22: OBJID | D22: NUMC | E22: 8 | F22: PK | G22: Object ID | H22: מזהה אובייקט
A23: 3 | C23: ARBPL | D23: CHAR | E23: 8 | F23: - | G23: Work center / resource code | H23: קוד משאב
A24: 4 | C24: WERKS | D24: CHAR | E24: 4 | F24: FK | G24: Plant | H24: מפעל
A25: 5 | C25: VERWE | D25: CHAR | E25: 4 | F25: FK | G25: Usage | H25: שימוש
A26: 6 | C26: VERAN | D26: CHAR | E26: 3 | F26: - | G26: Person responsible | H26: אחראי
A27: 7 | C27: PLANV | D27: CHAR | E27: 3 | F27: - | G27: Capacity planner group | H27: קבוצת מתכנן קיבולת
A29: ◆ טבלה CRTX - טקסטים של משאב (Work center / resource texts) | T-codes: CRC2/CRC3
A30: 8 | B30: CRTX | C30: OBJTY | D30: CHAR | E30: 2 | F30: PK/FK | G30: Object type | H30: סוג אובייקט | I30: FROM CRTX JOIN CRHD ON CRTX.OBJID = CRHD.OBJID AND CRTX.OBJTY = CRHD.OBJTY | J30: תיאורי המשאב הרב-לשוניים המוצגים בפעולות ובלוח התזמון. | K30: ללא שינוי. | L30: SAP Help - Work Center
A31: 9 | C31: OBJID | D31: NUMC | E31: 8 | F31: PK/FK | G31: Object ID | H31: מזהה אובייקט
A32: 10 | C32: SPRAS | D32: LANG | E32: 1 | F32: PK | G32: Language key | H32: שפה
A33: 11 | C33: KTEXT | D33: CHAR | E33: 40 | F33: - | G33: Description | H33: תיאור
A35: ◆ טבלה CRCO - שיוך משאב למרכז עלות (Work center to cost center assignment) | T-codes: CRC2 (Costing)
A36: 12 | B36: CRCO | C36: OBJTY | D36: CHAR | E36: 2 | F36: PK/FK | G36: Object type | H36: סוג אובייקט | I36: FROM CRCO JOIN CRHD ON CRCO.OBJID = CRHD.OBJID AND CRCO.OBJTY = CRHD.OBJTY | J36: מקשר את המשאב למרכז עלות ולסוגי פעילות (Activity Types) - בסיס לתמחיר שעות מכונה/עבודה בפק"ע ולהתחשבנות ב-ACDOCA. | K36: התחשבנות ב-Universal Journal (ACDOCA); הקצאה נשמרת. | L36: SAP Help - Work Center Costing
A37: 13 | C37: OBJID | D37: NUMC | E37: 8 | F37: PK/FK | G37: Object ID | H37: מזהה אובייקט
A38: 14 | C38: LANUM | D38: NUMC | E38: 3 | F38: PK | G38: Sequence number | H38: מספר רצף
A39: 15 | C39: KOKRS | D39: CHAR | E39: 4 | F39: FK | G39: Controlling area | H39: אזור בקרה
A40: 16 | C40: KOSTL | D40: CHAR | E40: 10 | F40: FK | G40: Cost center | H40: מרכז עלות
A41: 17 | C41: LSTAR | D41: CHAR | E41: 6 | F41: FK | G41: Activity type | H41: סוג פעילות
A43: ◆ טבלה CRCA - הקצאת קיבולת למשאב (Work center capacity allocation) | T-codes: CR11/CR12; CRC2
A44: 18 | B44: CRCA | C44: OBJTY | D44: CHAR | E44: 2 | F44: PK/FK | G44: Object type | H44: סוג אובייקט | I44: FROM CRCA JOIN CRHD ON CRCA.OBJID = CRHD.OBJID AND CRCA.OBJTY = CRHD.OBJTY | J44: מקשר את המשאב לקיבולת (KAKO) - שעות זמינות ביום/משמרת. בסיס לתכנון עומסים ולתזמון פק"ע בקו. | K44: ללא שינוי. | L44: SAP Help - Capacity
...

Sheet 6. פק"ע ייצור ומתכון בקרה (Proc
A1: ◄ חזרה למסך הראשי | C1: 6. פק"ע ייצור ומתכון בקרה (Process Order) | ECC 6.0 ➜ S/4HANA · CBC NEO
A2: מס' (#) | B2: טבלה (Table) | C2: שדה טכני (Field) | D2: סוג נתונים (Type) | E2: אורך (Len) | F2: מפתח (Key) | G2: English Term | H2: תרגום עברי (Hebrew) | I2: JOIN ON (SQL / CDS) | J2: הסבר פונקציונלי בעברית | K2: פער / הערת S/4HANA | L2: SAP Help
A3: 🔧 שכבה תפעולית (Operational Layer) - T-codes ◄► Fiori | ממשקים BAPI/IDoc/RFC | תוכניות רקע ודוחות
A4: מיפוי T-code ◄► Fiori App (ECC ◄► S/4HANA)
A5: ECC T-code | D5: S/4HANA Fiori App | I5: Fiori ID
A6: COR1 / COR2 / COR3 | D6: Create / Change / Display Process Order | I6: -
A7: COR6N (confirm) | D7: Confirm Production Operation | I7: F3372
A8: COIO / COOIS | D8: Process Order Information System | I8: -
A9: COHV (mass proc.) | D9: Mass Processing - Orders | I9: -
A10: ממשקים ובלוקים פונקציונליים: BAPIs / IDocs / RFCs (Extraction & Messaging)
A11: Type | C11: Name | G11: תיאור / Description
A12: BAPI | C12: BAPI_PROCORD_CREATE / _RELEASE | G12: יצירה/שחרור פק"ע ייצור
A13: BAPI | C13: BAPI_PROCORDCONF_CREATE_TT | G13: דיווח ביצוע פק"ע (Time Ticket)
A14: IDoc | C14: LOIPRO | G14: שליחת פק"ע/הוראות ייצור ל-MES (Zetes/Daymax)
A15: IDoc | C15: PPCC1 (PP-PI message) | G15: הודעות תהליך/דיווח מהקו חזרה ל-SAP
A16: תוכניות רקע ודוחות סטנדרטיים (Background Programs / Reports)
A17: Program / Report | E17: תיאור ומטרה / Usage & Trigger
A18: MD01 / MD01N (MRP Live) | E18: הרצת MRP - תכנון חומרים וייצור
A19: COHV / RCO_BATCH_SCHEDULE | E19: עיבוד המוני ותזמון אצוות פק"ע
A20: CO41 / CO48 (convert) | E20: המרת פק"ע מתוכננת לפק"ע ייצור
A22: ◆ טבלה AUFK - נתוני אב של פקודת ייצור (Order master data) | T-codes: COR1/COR2/COR3; COOIS
A23: 1 | B23: AUFK | C23: AUFNR | D23: CHAR | E23: 12 | F23: PK | G23: Order number | H23: מספר פק"ע | I23: (header - process order master) | J23: כותרת פק"ע הייצור (Process Order). נוצרת מגרסת ייצור (MKAL) + מתכון. שחרור הפק"ע מייצר Control Recipe ושולח הוראות תהליך לקו דרך IDoc. מעקב ב-COR2/COIO. | K23: מודל מותאם; עלויות ב-ACDOCA. | L23: SAP Help - Process Order
A24: 2 | C24: AUART | D24: CHAR | E24: 4 | F24: FK | G24: Order type | H24: סוג פק"ע
A25: 3 | C25: WERKS | D25: CHAR | E25: 4 | F25: FK | G25: Plant | H25: מפעל
A26: 4 | C26: OBJNR | D26: CHAR | E26: 22 | F26: FK | G26: Object number (status) | H26: מפתח אובייקט
A27: 5 | C27: KTEXT | D27: CHAR | E27: 40 | F27: - | G27: Description | H27: תיאור
A29: ◆ טבלה AFKO - כותרת פקודת ייצור (Order header data) | T-codes: COR2
A30: 6 | B30: AFKO | C30: AUFNR | D30: CHAR | E30: 12 | F30: PK/FK | G30: Order number | H30: מספר פק"ע | I30: FROM AFKO JOIN AUFK ON AFKO.AUFNR = AUFK.AUFNR | J30: נתוני הייצור של הפק"ע: כמות, מועדים, גרסת ייצור (VERID), מתכון. AUFPL מקשר לפעולות. בסיס לתזמון ולפליטת חומרים. | K30: מותאם (תואם). | L30: SAP Help - Order Header
A31: 7 | C31: GAMNG | D31: QUAN | E31: 13 | F31: - | G31: Total order quantity | H31: כמות פק"ע
A32: 8 | C32: GMEIN | D32: UNIT | E32: 3 | F32: FK | G32: Unit of measure | H32: יחידת מידה
A33: 9 | C33: VERID | D33: CHAR | E33: 4 | F33: FK | G33: Production version | H33: גרסת ייצור
A34: 10 | C34: AUFPL | D34: NUMC | E34: 10 | F34: FK | G34: Routing number of operations | H34: מספר תוכנית פעולות
A35: 11 | C35: GLTRP | D35: DATS | E35: 8 | F35: - | G35: Basic finish date | H35: תאריך סיום בסיסי
A37: ◆ טבלה AFPO - פריט פקודת ייצור (Order item) | T-codes: COR3
A38: 12 | B38: AFPO | C38: AUFNR | D38: CHAR | E38: 12 | F38: PK/FK | G38: Order number | H38: מספר פק"ע | I38: FROM AFPO JOIN AFKO ON AFPO.AUFNR = AFKO.AUFNR | J38: פריט הפק"ע: החומר המיוצר, כמות, מחסן קליטה, אצווה. נקודת קליטת המוצר המוגמר למלאי. | K38: מותאם (תואם). | L38: SAP Help - Order Item
A39: 13 | C39: POSNR | D39: NUMC | E39: 6 | F39: PK | G39: Order item number | H39: מספר פריט
A40: 14 | C40: MATNR | D40: CHAR | E40: 18->40 | F40: FK | G40: Material produced | H40: חומר מיוצר
A41: 15 | C41: PSMNG | D41: QUAN | E41: 13 | F41: - | G41: Order item quantity | H41: כמות פריט
A42: 16 | C42: CHARG | D42: CHAR | E42: 10 | F42: - | G42: Batch | H42: אצווה
A44: ◆ טבלה AFVC - פעולות פקודת הייצור (Order operations) | T-codes: COR2
...

Sheet 7. קונפיגורציה (Customizing)
A1: ◄ חזרה למסך הראשי | C1: 7. קונפיגורציה (Customizing) | ECC 6.0 ➜ S/4HANA · CBC NEO
A2: מס' (#) | B2: טבלה (Table) | C2: שדה טכני (Field) | D2: סוג נתונים (Type) | E2: אורך (Len) | F2: מפתח (Key) | G2: English Term | H2: תרגום עברי (Hebrew) | I2: JOIN ON (SQL / CDS) | J2: הסבר פונקציונלי בעברית | K2: פער / הערת S/4HANA | L2: SAP Help
A3: 🔧 שכבה תפעולית (Operational Layer) - T-codes ◄► Fiori | ממשקים BAPI/IDoc/RFC | תוכניות רקע ודוחות
A4: מיפוי T-code ◄► Fiori App (ECC ◄► S/4HANA)
A5: ECC T-code | D5: S/4HANA Fiori App | I5: Fiori ID
A6: COR4 (order type) | D6: Configure Order Types (SPRO) | I6: -
A7: OPL8 (plant params) | D7: Order Type-Dependent Parameters | I7: -
A8: BS02 (status profile) | D8: Maintain Status Profile | I8: -
A9: BP (Business Partner) | D9: Manage Business Partner Master Data | I9: -
A10: ממשקים ובלוקים פונקציונליים: BAPIs / IDocs / RFCs (Extraction & Messaging)
A11: Type | C11: Name | G11: תיאור / Description
A12: IDoc | C12: LOIPRO | G12: פק"ע/הוראות ייצור ל-MES
A13: BAPI | C13: BAPI_BUPA_CREATE_FROM_DATA | G13: יצירת שותף עסקי (BP)
A14: FM | C14: CVI_VENDOR_TO_BP_CONVERT | G14: המרת ספק ל-BP (CVI)
A15: RFC | C15: STATUS_CHANGE_INTERN | G15: שינוי סטטוס פנימי
A16: תוכניות רקע ודוחות סטנדרטיים (Background Programs / Reports)
A17: Program / Report | E17: תיאור ומטרה / Usage & Trigger
A18: RBDMIDOC | E18: יצירת IDocs להפצה (MATMAS/LOIPRO)
A19: MDS_LOAD_COCKPIT | E19: סנכרון Customer/Vendor Integration ל-BP
A20: RHALTD00 / RCOZP | E20: עיבוד/בדיקת קונפיגורציה
A22: ◆ טבלה T134 - סוגי חומר (Customizing) (Material types) | T-codes: OMS2; SPRO
A23: 1 | B23: T134 | C23: MTART | D23: CHAR | E23: 4 | F23: PK | G23: Material type | H23: סוג חומר | I23: FROM MARA JOIN T134 ON MARA.MTART = T134.MTART | J23: מגדיר סוגי חומר (ROH גלם, FERT מוגמר, HALB ביניים, VERP אריזה) ושולט באילו תצוגות/שדות חובה. בסיס לסיווג כל חומרי CBC. | K23: ללא שינוי (Customizing). | L23: SAP Help - Material Types
A24: 2 | C24: MBRSH | D24: CHAR | E24: 1 | F24: - | G24: Industry sector | H24: ענף
A25: 3 | C25: KKREF | D25: CHAR | E25: 4 | F25: - | G25: Account category reference | H25: הפניית קטגוריית חשבון
A27: ◆ טבלה T134T - טקסטים לסוגי חומר (Material type descriptions) | T-codes: OMS2
A28: 4 | B28: T134T | C28: MTART | D28: CHAR | E28: 4 | F28: PK/FK | G28: Material type | H28: סוג חומר | I28: FROM T134T JOIN T134 ON T134T.MTART = T134.MTART | J28: תיאורי סוגי החומר הרב-לשוניים. | K28: ללא שינוי. | L28: SAP Help - Material Types
A29: 5 | C29: SPRAS | D29: LANG | E29: 1 | F29: PK | G29: Language key | H29: שפה
A30: 6 | C30: MTBEZ | D30: CHAR | E30: 25 | F30: - | G30: Material type description | H30: תיאור סוג חומר
A32: ◆ טבלה T023 - קבוצות חומר (Customizing) (Material groups) | T-codes: OMSF; SPRO
A33: 7 | B33: T023 | C33: MATKL | D33: CHAR | E33: 9 | F33: PK | G33: Material group | H33: קבוצת חומר | I33: FROM MARA JOIN T023 ON MARA.MATKL = T023.MATKL | J33: מגדיר קבוצות חומר לקיבוץ דיווחי וניתוח רכש/ייצור - לדוגמה 'תרכיזים', 'בקבוקי PET', 'פחיות'. | K33: ללא שינוי. | L33: SAP Help - Material Groups
A34: 8 | C34: BKLAS | D34: CHAR | E34: 4 | F34: - | G34: Valuation class | H34: מחלקת הערכה
A36: ◆ טבלה T023T - טקסטים לקבוצות חומר (Material group descriptions) | T-codes: OMSF
A37: 9 | B37: T023T | C37: MATKL | D37: CHAR | E37: 9 | F37: PK/FK | G37: Material group | H37: קבוצת חומר | I37: FROM T023T JOIN T023 ON T023T.MATKL = T023.MATKL | J37: תיאורי קבוצות החומר הרב-לשוניים. | K37: ללא שינוי. | L37: SAP Help - Material Groups
A38: 10 | C38: SPRAS | D38: LANG | E38: 1 | F38: PK | G38: Language key | H38: שפה
A39: 11 | C39: WGBEZ | D39: CHAR | E39: 20 | F39: - | G39: Material group description | H39: תיאור קבוצת חומר
A41: ◆ טבלה T399X - פרמטרי בקרת ייצור למפעל (Plant production control parameters) | T-codes: OPL8; SPRO
A42: 12 | B42: T399X | C42: WERKS | D42: CHAR | E42: 4 | F42: PK | G42: Plant | H42: מפעל | I42: FROM AUFK JOIN T399X ON AUFK.WERKS = T399X.WERKS AND AUFK.AUART = T399X.AUART | J42: פרמטרי בקרה לפק"ע לפי מפעל/סוג פק"ע: זמינות, אופק שחרור, פרופיל סטטוס, IDoc. כאן מוגדרת זרימת ה-Control Recipe ל-Zetes/Daymax. | K42: ללא שינוי (Customizing). | L42: SAP Help - Order Type Plant Parameters
A43: 13 | C43: AUART | D43: CHAR | E43: 4 | F43: PK | G43: Order type | H43: סוג פק"ע
A44: 14 | C44: APROFIL | D44: CHAR | E44: 4 | F44: - | G44: Availability check profile | H44: פרופיל בדיקת זמינות
A45: 15 | C45: TERHO | D45: NUMC | E45: 3 | F45: - | G45: Scheduling / release horizon | H45: אופק שחרור
...

Sheet Cockpit מעקב מיגרציה
A1: ◄ חזרה למסך הראשי | C1: Cockpit מעקב מיגרציה - PP-PI Migration Tracking (Project NEO)
B2: KPI & Summary - סיכום חי (COUNTIF; בסיס מוכן לגרף נייטיב ב-2 קליקים) | K2: Status | L2: Count
B3: =COUNTA($C$8:$C$72) | C3: =COUNTIF($D$8:$D$72,"Done") | D3: =COUNTIF($D$8:$D$72,"Tested") | E3: =COUNTIF($D$8:$D$72,"In analysis")+COUNTIF($D$8:$D$72,"In conversion") | F3: =COUNTIF($D$8:$D$72,"Not started") | G3: =IFERROR(COUNTIF($D$8:$D$72,"Done")/COUNTA($C$8:$C$72),0) | K3: Not started | L3: =COUNTIF($D$8:$D$72,$K3)
B4: סה"כ | C4: Done | D4: Tested | E4: In Progress | F4: Open | G4: % Done | K4: In analysis | L4: =COUNTIF($D$8:$D$72,$K4)
K5: In conversion | L5: =COUNTIF($D$8:$D$72,$K5)
K6: Tested | L6: =COUNTIF($D$8:$D$72,$K6)
A7: מס' (#) | B7: מודול / נושא | C7: טבלה | D7: סטטוס מעבר (Status) | E7: קישור | F7: תיאור | K7: Done | L7: =COUNTIF($D$8:$D$72,$K7)
A8: 1 | B8: 1. נתוני אב חומר ויחידות מידה (Material & UoM) | C8: MARA | D8: Not started | E8: =HYPERLINK("#'"&"1. נתוני אב חומר ויחידות מידה ("&"'!A22","➜ פתח") | F8: נתוני אב חומר כלליים
A9: 2 | B9: 1. נתוני אב חומר ויחידות מידה (Material & UoM) | C9: MAKT | D9: Not started | E9: =HYPERLINK("#'"&"1. נתוני אב חומר ויחידות מידה ("&"'!A32","➜ פתח") | F9: תיאורי חומר (טקסטים)
A10: 3 | B10: 1. נתוני אב חומר ויחידות מידה (Material & UoM) | C10: MARC | D10: Not started | E10: =HYPERLINK("#'"&"1. נתוני אב חומר ויחידות מידה ("&"'!A38","➜ פתח") | F10: נתוני חומר ברמת מפעל
A11: 4 | B11: 1. נתוני אב חומר ויחידות מידה (Material & UoM) | C11: MARD | D11: Not started | E11: =HYPERLINK("#'"&"1. נתוני אב חומר ויחידות מידה ("&"'!A48","➜ פתח") | F11: נתוני חומר ברמת מחסן/מלאי
A12: 5 | B12: 1. נתוני אב חומר ויחידות מידה (Material & UoM) | C12: MARM | D12: Not started | E12: =HYPERLINK("#'"&"1. נתוני אב חומר ויחידות מידה ("&"'!A55","➜ פתח") | F12: המרות יחידות מידה חלופיות
A13: 6 | B13: 1. נתוני אב חומר ויחידות מידה (Material & UoM) | C13: MEAN | D13: Not started | E13: =HYPERLINK("#'"&"1. נתוני אב חומר ויחידות מידה ("&"'!A63","➜ פתח") | F13: ברקודים / EAN לחומר
A14: 7 | B14: 1. נתוני אב חומר ויחידות מידה (Material & UoM) | C14: MBEW | D14: Not started | E14: =HYPERLINK("#'"&"1. נתוני אב חומר ויחידות מידה ("&"'!A70","➜ פתח") | F14: הערכת חומר (Valuation)
A15: 8 | B15: 1. נתוני אב חומר ויחידות מידה (Material & UoM) | C15: MVKE | D15: Not started | E15: =HYPERLINK("#'"&"1. נתוני אב חומר ויחידות מידה ("&"'!A78","➜ פתח") | F15: נתוני חומר ברמת מכירות
A16: 9 | B16: 1. נתוני אב חומר ויחידות מידה (Material & UoM) | C16: MLAN | D16: Not started | E16: =HYPERLINK("#'"&"1. נתוני אב חומר ויחידות מידה ("&"'!A84","➜ פתח") | F16: נתוני מס לחומר (לפי מדינה)
A17: 10 | B17: 1. נתוני אב חומר ויחידות מידה (Material & UoM) | C17: MLGN | D17: Not started | E17: =HYPERLINK("#'"&"1. נתוני אב חומר ויחידות מידה ("&"'!A89","➜ פתח") | F17: נתוני חומר ברמת מחסן (WM)
A18: 11 | B18: 1. נתוני אב חומר ויחידות מידה (Material & UoM) | C18: MLGT | D18: Not started | E18: =HYPERLINK("#'"&"1. נתוני אב חומר ויחידות מידה ("&"'!A95","➜ פתח") | F18: נתוני חומר לפי טיפוס אחסון
A19: 12 | B19: 1. נתוני אב חומר ויחידות מידה (Material & UoM) | C19: MDMA | D19: Not started | E19: =HYPERLINK("#'"&"1. נתוני אב חומר ויחידות מידה ("&"'!A101","➜ פתח") | F19: אזורי MRP לחומר
A20: 13 | B20: 1. נתוני אב חומר ויחידות מידה (Material & UoM) | C20: QMAT | D20: Not started | E20: =HYPERLINK("#'"&"1. נתוני אב חומר ויחידות מידה ("&"'!A107","➜ פתח") | F20: הגדרות בדיקת איכות לחומר
A21: 14 | B21: 1. נתוני אב חומר ויחידות מידה (Material & UoM) | C21: MCH1 | D21: Not started | E21: =HYPERLINK("#'"&"1. נתוני אב חומר ויחידות מידה ("&"'!A113","➜ פתח") | F21: אצוות חומר (Batches)
A22: 15 | B22: 1. נתוני אב חומר ויחידות מידה (Material & UoM) | C22: MCHA | D22: Not started | E22: =HYPERLINK("#'"&"1. נתוני אב חומר ויחידות מידה ("&"'!A122","➜ פתח") | F22: אצוות חומר ברמת מפעל
A23: 16 | B23: 1. נתוני אב חומר ויחידות מידה (Material & UoM) | C23: T006 | D23: Not started | E23: =HYPERLINK("#'"&"1. נתוני אב חומר ויחידות מידה ("&"'!A128","➜ פתח") | F23: יחידות מידה (Customizing)
A24: 17 | B24: 2. עץ מוצר (BOM) | C24: MAST | D24: Not started | E24: =HYPERLINK("#'"&"2. עץ מוצר (BOM)"&"'!A21","➜ פתח") | F24: קישור חומר לעץ מוצר
A25: 18 | B25: 2. עץ מוצר (BOM) | C25: STKO | D25: Not started | E25: =HYPERLINK("#'"&"2. עץ מוצר (BOM)"&"'!A28","➜ פתח") | F25: כותרת עץ מוצר
A26: 19 | B26: 2. עץ מוצר (BOM) | C26: STPO | D26: Not started | E26: =HYPERLINK("#'"&"2. עץ מוצר (BOM)"&"'!A36","➜ פתח") | F26: פריטי עץ מוצר (רכיבים)
A27: 20 | B27: 2. עץ מוצר (BOM) | C27: STAS | D27: Not started | E27: =HYPERLINK("#'"&"2. עץ מוצר (BOM)"&"'!A47","➜ פתח") | F27: בחירת פריטי עץ מוצר
A28: 21 | B28: 2. עץ מוצר (BOM) | C28: STZU | D28: Not started | E28: =HYPERLINK("#'"&"2. עץ מוצר (BOM)"&"'!A54","➜ פתח") | F28: טבלת היסטוריה/קישור לעץ מוצר
A29: 22 | B29: 2. עץ מוצר (BOM) | C29: STPU | D29: Not started | E29: =HYPERLINK("#'"&"2. עץ מוצר (BOM)"&"'!A60","➜ פתח") | F29: טקסטים ארוכים לפריט עץ מוצר
A30: 23 | B30: 2. עץ מוצר (BOM) | C30: KDST | D30: Not started | E30: =HYPERLINK("#'"&"2. עץ מוצר (BOM)"&"'!A65","➜ פתח") | F30: שימוש עץ מוצר בהזמנת לקוח
A31: 24 | B31: 3. מתכון ייצור ופעולות (Master Recipe) | C31: PLKO | D31: Not started | E31: =HYPERLINK("#'"&"3. מתכון ייצור ופעולות (Master "&"'!A21","➜ פתח") | F31: כותרת מתכון ייצור / רשימת פעולות
A32: 25 | B32: 3. מתכון ייצור ופעולות (Master Recipe) | C32: PLPO | D32: Not started | E32: =HYPERLINK("#'"&"3. מתכון ייצור ופעולות (Master "&"'!A30","➜ פתח") | F32: פעולות/פאזות במתכון
A33: 26 | B33: 3. מתכון ייצור ופעולות (Master Recipe) | C33: PLAS | D33: Not started | E33: =HYPERLINK("#'"&"3. מתכון ייצור ופעולות (Master "&"'!A41","➜ פתח") | F33: שיוך/בחירת פעולות לרשימה
A34: 27 | B34: 3. מתכון ייצור ופעולות (Master Recipe) | C34: PLFL | D34: Not started | E34: =HYPERLINK("#'"&"3. מתכון ייצור ופעולות (Master "&"'!A49","➜ פתח") | F34: רצפים במתכון
A35: 28 | B35: 3. מתכון ייצור ופעולות (Master Recipe) | C35: PLMZ | D35: Not started | E35: =HYPERLINK("#'"&"3. מתכון ייצור ופעולות (Master "&"'!A55","➜ פתח") | F35: שיוך רכיבים לפעולות
A36: 29 | B36: 3. מתכון ייצור ופעולות (Master Recipe) | C36: PLMK | D36: Not started | E36: =HYPERLINK("#'"&"3. מתכון ייצור ופעולות (Master "&"'!A62","➜ פתח") | F36: מאפייני בדיקה במתכון
A37: 30 | B37: 3. מתכון ייצור ופעולות (Master Recipe) | C37: MAPL | D37: Not started | E37: =HYPERLINK("#'"&"3. מתכון ייצור ופעולות (Master "&"'!A70","➜ פתח") | F37: שיוך חומר למתכון/רשימת פעולות
A38: 31 | B38: 3. מתכון ייצור ופעולות (Master Recipe) | C38: FHMI | D38: Not started | E38: =HYPERLINK("#'"&"3. מתכון ייצור ופעולות (Master "&"'!A77","➜ פתח") | F38: שיוך כלי עזר ייצור (PRT) לפעולה
A39: 32 | B39: 3. מתכון ייצור ופעולות (Master Recipe) | C39: PLZU | D39: Not started | E39: =HYPERLINK("#'"&"3. מתכון ייצור ופעולות (Master "&"'!A83","➜ פתח") | F39: קישור היסטוריית רשימת פעולות
A40: 33 | B40: 3. מתכון ייצור ופעולות (Master Recipe) | C40: TC60 | D40: Not started | E40: =HYPERLINK("#'"&"3. מתכון ייצור ופעולות (Master "&"'!A88","➜ פתח") | F40: מאפייני הוראות תהליך (PI)
...

Sheet ER - Join Map
A1: ◄ חזרה למסך הראשי | C1: ER - Join Map - JOIN ON (SQL / CDS Views) · CBC NEO
A2: מס' (#) | B2: טבלה (Child) | C2: JOIN ON (SQL / CDS Views Syntax) | D2: תיאור
A3: 1 | B3: MAKT | C3: FROM MAKT JOIN MARA ON MAKT.MATNR = MARA.MATNR | D3: תיאורי חומר (טקסטים)
A4: 2 | B4: MARC | C4: FROM MARC JOIN MARA ON MARC.MATNR = MARA.MATNR | D4: נתוני חומר ברמת מפעל
A5: 3 | B5: MARD | C5: FROM MARD JOIN MARC ON MARD.MATNR = MARC.MATNR AND MARD.WERKS = MARC.WERKS | D5: נתוני חומר ברמת מחסן/מלאי
A6: 4 | B6: MARM | C6: FROM MARM JOIN MARA ON MARM.MATNR = MARA.MATNR | D6: המרות יחידות מידה חלופיות
A7: 5 | B7: MEAN | C7: FROM MEAN JOIN MARA ON MEAN.MATNR = MARA.MATNR | D7: ברקודים / EAN לחומר
A8: 6 | B8: MBEW | C8: FROM MBEW JOIN MARA ON MBEW.MATNR = MARA.MATNR | D8: הערכת חומר (Valuation)
A9: 7 | B9: MVKE | C9: FROM MVKE JOIN MARA ON MVKE.MATNR = MARA.MATNR | D9: נתוני חומר ברמת מכירות
A10: 8 | B10: MLAN | C10: FROM MLAN JOIN MARA ON MLAN.MATNR = MARA.MATNR | D10: נתוני מס לחומר (לפי מדינה)
A11: 9 | B11: MLGN | C11: FROM MLGN JOIN MARA ON MLGN.MATNR = MARA.MATNR | D11: נתוני חומר ברמת מחסן (WM)
A12: 10 | B12: MLGT | C12: FROM MLGT JOIN MLGN ON MLGT.MATNR = MLGN.MATNR AND MLGT.LGNUM = MLGN.LGNUM | D12: נתוני חומר לפי טיפוס אחסון
A13: 11 | B13: MDMA | C13: FROM MDMA JOIN MARC ON MDMA.MATNR = MARC.MATNR AND MDMA.WERKS = MARC.WERKS | D13: אזורי MRP לחומר
A14: 12 | B14: QMAT | C14: FROM QMAT JOIN MARC ON QMAT.MATNR = MARC.MATNR AND QMAT.WERKS = MARC.WERKS | D14: הגדרות בדיקת איכות לחומר
... A64: 62 | B64: TC22 | C64: FROM PLPO JOIN TC22 ON PLPO.STEUS = TC22.STEUS | D64: מפתחות בקרת תהליך/פעולה (PI Control)
